Workbook

Sheet Encoder-Track1
B2: Duration (samples) | C2: =M39*300000 -> 72000000
B3: Sampling rate | C3: 24000
B4: Duration (sec) | C4: =C2/C3 -> 3000
B7: Layer Name | C7: block ID | D7: kernel size | E7: input channels | F7: output channels | G7: dilation | H7: stride | I7: alignment | J7: FOV left (in samples) | K7: FOV right (in samples) | L7: padding left | M7: padding right | N7: extra padding right | O7: padded input length | P7: output length | Q7: #Params | R7: #MAC | S7: MMAC/s
B8: Input Conv | C8: Input Conv | D8: 7 | E8: 1 | F8: 8 | G8: 1 | H8: 1 | I8: 1 | J8: =$I8*($D8-1)*$G8 -> 6 | K8: =(1-$I8)*($D8-1)*$G8 -> 0 | L8: =(($D8-1)*$G8+1-$H8)*$I8 -> 6 | M8: =(($D8-1)*$G8+1-$H8)*(1-$I8) -> 0 | N8: =CEILING((C2-H8)/H8+1, 1)*H8-C2 -> 0 | O8: =C2+L8+M8+N8 -> 72000006 | P8: =(O8-G8*(D8-1)-1)/H8+1 -> 72000000 | Q8: =D8*E8*F8 -> 56 | R8: =P8*F8*D8*E8 -> 4032000000 | S8: =R8/$C$4/10^6 -> 1.344
B9: Conv1_1 | C9: Residual Stack 1 | D9: 5 | E9: =F8 -> 8 | F9: =F8 -> 8 | G9: 3 | H9: 1 | I9: 1 | J9: =$I9*($D9-1)*$G9*PRODUCT(H8:H8) -> 12 | K9: =(1-$I9)*($D9-1)*$G9*PRODUCT(H8:H8) -> 0 | L9: =(($D9-1)*$G9+1-$H9)*$I9 -> 12 | M9: =(($D9-1)*$G9+1-$H9)*(1-$I9) -> 0 | N9: =CEILING((P8-H9)/H9+1, 1)*H9-P8 -> 0 | O9: =P8+L9+M9+N9 -> 72000012 | P9: =(O9-G9*(D9-1)-1)/H9+1 -> 72000000 | Q9: =D9*E9*F9 -> 320 | R9: =P9*F9*D9*E9 -> 23040000000 | S9: =R9/$C$4/10^6 -> 7.68
B10: Conv1_2 | C10: Residual Stack 1 | D10: 1 | E10: =F9 -> 8 | F10: =F8 -> 8 | G10: 1 | H10: 1 | I10: 1 | J10: =$I10*($D10-1)*$G10*PRODUCT(H8:H9) -> 0 | K10: =(1-$I10)*($D10-1)*$G10*PRODUCT(H8:H9) -> 0 | L10: =(($D10-1)*$G10+1-$H10)*$I10 -> 0 | M10: =(($D10-1)*$G10+1-$H10)*(1-$I10) -> 0 | N10: =CEILING((P9-H10)/H10+1, 1)*H10-P9 -> 0 | O10: =P9+L10+M10+N10 -> 72000000 | P10: =(O10-G10*(D10-1)-1)/H10+1 -> 72000000 | Q10: =D10*E10*F10 -> 64 | R10: =P10*F10*D10*E10 -> 4608000000 | S10: =R10/$C$4/10^6 -> 1.536
B11: Conv1_3 | C11: Residual Stack 1 | D11: 5 | E11: =F10 -> 8 | F11: =F8 -> 8 | G11: 9 | H11: 1 | I11: 1 | J11: =$I11*($D11-1)*$G11*PRODUCT(H8:H10) -> 36 | K11: =(1-$I11)*($D11-1)*$G11*PRODUCT(H8:H10) -> 0 | L11: =(($D11-1)*$G11+1-$H11)*$I11 -> 36 | M11: =(($D11-1)*$G11+1-$H11)*(1-$I11) -> 0 | N11: =CEILING((P10-H11)/H11+1, 1)*H11-P10 -> 0 | O11: =P10+L11+M11+N11 -> 72000036 | P11: =(O11-G11*(D11-1)-1)/H11+1 -> 72000000 | Q11: =D11*E11*F11 -> 320 | R11: =P11*F11*D11*E11 -> 23040000000 | S11: =R11/$C$4/10^6 -> 7.68
B12: Conv1_4 | C12: Residual Stack 1 | D12: 1 | E12: =F11 -> 8 | F12: =F8 -> 8 | G12: 1 | H12: 1 | I12: 1 | J12: =$I12*($D12-1)*$G12*PRODUCT(H8:H11) -> 0 | K12: =(1-$I12)*($D12-1)*$G12*PRODUCT(H8:H11) -> 0 | L12: =(($D12-1)*$G12+1-$H12)*$I12 -> 0 | M12: =(($D12-1)*$G12+1-$H12)*(1-$I12) -> 0 | N12: =CEILING((P11-H12)/H12+1, 1)*H12-P11 -> 0 | O12: =P11+L12+M12+N12 -> 72000000 | P12: =(O12-G12*(D12-1)-1)/H12+1 -> 72000000 | Q12: =D12*E12*F12 -> 64 | R12: =P12*F12*D12*E12 -> 4608000000 | S12: =R12/$C$4/10^6 -> 1.536
B13: Conv1_5 | C13: Residual Stack 1 | D13: 5 | E13: =F12 -> 8 | F13: =F8 -> 8 | G13: 27 | H13: 1 | I13: 1 | J13: =$I13*($D13-1)*$G13*PRODUCT(H8:H12) -> 108 | K13: =(1-$I13)*($D13-1)*$G13*PRODUCT(H8:H12) -> 0 | L13: =(($D13-1)*$G13+1-$H13)*$I13 -> 108 | M13: =(($D13-1)*$G13+1-$H13)*(1-$I13) -> 0 | N13: =CEILING((P12-H13)/H13+1, 1)*H13-P12 -> 0 | O13: =P12+L13+M13+N13 -> 72000108 | P13: =(O13-G13*(D13-1)-1)/H13+1 -> 72000000 | Q13: =D13*E13*F13 -> 320 | R13: =P13*F13*D13*E13 -> 23040000000 | S13: =R13/$C$4/10^6 -> 7.68
B14: Conv1_6 | C14: Residual Stack 1 | D14: 1 | E14: =F13 -> 8 | F14: =F8 -> 8 | G14: 1 | H14: 1 | I14: 1 | J14: =$I14*($D14-1)*$G14*PRODUCT(H8:H13) -> 0 | K14: =(1-$I14)*($D14-1)*$G14*PRODUCT(H8:H13) -> 0 | L14: =(($D14-1)*$G14+1-$H14)*$I14 -> 0 | M14: =(($D14-1)*$G14+1-$H14)*(1-$I14) -> 0 | N14: =CEILING((P13-H14)/H14+1, 1)*H14-P13 -> 0 | O14: =P13+L14+M14+N14 -> 72000000 | P14: =(O14-G14*(D14-1)-1)/H14+1 -> 72000000 | Q14: =D14*E14*F14 -> 64 | R14: =P14*F14*D14*E14 -> 4608000000 | S14: =R14/$C$4/10^6 -> 1.536
B15: Conv1_7 | C15: Strided Conv 1 | D15: =2*H15 -> 6 | E15: =F14 -> 8 | F15: 16 | G15: 1 | H15: 3 | I15: 1 | J15: =$I15*($D15-1)*$G15*PRODUCT(H8:H14) -> 5 | K15: =(1-$I15)*($D15-1)*$G15*PRODUCT(H8:H14) -> 0 | L15: =(($D15-1)*$G15+1-$H15)*$I15 -> 3 | M15: =(($D15-1)*$G15+1-$H15)*(1-$I15) -> 0 | N15: =CEILING((P14-H15)/H15+1, 1)*H15-P14 -> 0 | O15: =P14+L15+M15+N15 -> 72000003 | P15: =(O15-G15*(D15-1)-1)/H15+1 -> 24000000 | Q15: =D15*E15*F15 -> 768 | R15: =P15*F15*D15*E15 -> 18432000000 | S15: =R15/$C$4/10^6 -> 6.144
B16: Conv2_1 | C16: Residual Stack 2 | D16: 5 | E16: =F15 -> 16 | F16: =F15 -> 16 | G16: 3 | H16: 1 | I16: 1 | J16: =$I16*($D16-1)*$G16*PRODUCT(H8:H15) -> 36 | K16: =(1-$I16)*($D16-1)*$G16*PRODUCT(H8:H15) -> 0 | L16: =(($D16-1)*$G16+1-$H16)*$I16 -> 12 | M16: =(($D16-1)*$G16+1-$H16)*(1-$I16) -> 0 | N16: =CEILING((P15-H16)/H16+1, 1)*H16-P15 -> 0 | O16: =P15+L16+M16+N16 -> 24000012 | P16: =(O16-G16*(D16-1)-1)/H16+1 -> 24000000 | Q16: =D16*E16*F16 -> 1280 | R16: =P16*F16*D16*E16 -> 30720000000 | S16: =R16/$C$4/10^6 -> 10.24
B17: Conv2_2 | C17: Residual Stack 2 | D17: 1 | E17: =F16 -> 16 | F17: =F15 -> 16 | G17: 1 | H17: 1 | I17: 1 | J17: =$I17*($D17-1)*$G17*PRODUCT(H8:H16) -> 0 | K17: =(1-$I17)*($D17-1)*$G17*PRODUCT(H8:H16) -> 0 | L17: =(($D17-1)*$G17+1-$H17)*$I17 -> 0 | M17: =(($D17-1)*$G17+1-$H17)*(1-$I17) -> 0 | N17: =CEILING((P16-H17)/H17+1, 1)*H17-P16 -> 0 | O17: =P16+L17+M17+N17 -> 24000000 | P17: =(O17-G17*(D17-1)-1)/H17+1 -> 24000000 | Q17: =D17*E17*F17 -> 256 | R17: =P17*F17*D17*E17 -> 6144000000 | S17: =R17/$C$4/10^6 -> 2.048
B18: Conv2_3 | C18: Residual Stack 2 | D18: 5 | E18: =F17 -> 16 | F18: =F15 -> 16 | G18: 9 | H18: 1 | I18: 1 | J18: =$I18*($D18-1)*$G18*PRODUCT(H8:H17) -> 108 | K18: =(1-$I18)*($D18-1)*$G18*PRODUCT(H8:H17) -> 0 | L18: =(($D18-1)*$G18+1-$H18)*$I18 -> 36 | M18: =(($D18-1)*$G18+1-$H18)*(1-$I18) -> 0 | N18: =CEILING((P17-H18)/H18+1, 1)*H18-P17 -> 0 | O18: =P17+L18+M18+N18 -> 24000036 | P18: =(O18-G18*(D18-1)-1)/H18+1 -> 24000000 | Q18: =D18*E18*F18 -> 1280 | R18: =P18*F18*D18*E18 -> 30720000000 | S18: =R18/$C$4/10^6 -> 10.24
B19: Conv2_4 | C19: Residual Stack 2 | D19: 1 | E19: =F18 -> 16 | F19: =F15 -> 16 | G19: 1 | H19: 1 | I19: 1 | J19: =$I19*($D19-1)*$G19*PRODUCT(H8:H18) -> 0 | K19: =(1-$I19)*($D19-1)*$G19*PRODUCT(H8:H18) -> 0 | L19: =(($D19-1)*$G19+1-$H19)*$I19 -> 0 | M19: =(($D19-1)*$G19+1-$H19)*(1-$I19) -> 0 | N19: =CEILING((P18-H19)/H19+1, 1)*H19-P18 -> 0 | O19: =P18+L19+M19+N19 -> 24000000 | P19: =(O19-G19*(D19-1)-1)/H19+1 -> 24000000 | Q19: =D19*E19*F19 -> 256 | R19: =P19*F19*D19*E19 -> 6144000000 | S19: =R19/$C$4/10^6 -> 2.048
B20: Conv2_5 | C20: Residual Stack 2 | D20: 5 | E20: =F19 -> 16 | F20: =F15 -> 16 | G20: 27 | H20: 1 | I20: 1 | J20: =$I20*($D20-1)*$G20*PRODUCT(H8:H19) -> 324 | K20: =(1-$I20)*($D20-1)*$G20*PRODUCT(H8:H19) -> 0 | L20: =(($D20-1)*$G20+1-$H20)*$I20 -> 108 | M20: =(($D20-1)*$G20+1-$H20)*(1-$I20) -> 0 | N20: =CEILING((P19-H20)/H20+1, 1)*H20-P19 -> 0 | O20: =P19+L20+M20+N20 -> 24000108 | P20: =(O20-G20*(D20-1)-1)/H20+1 -> 24000000 | Q20: =D20*E20*F20 -> 1280 | R20: =P20*F20*D20*E20 -> 30720000000 | S20: =R20/$C$4/10^6 -> 10.24
B21: Conv2_6 | C21: Residual Stack 2 | D21: 1 | E21: =F20 -> 16 | F21: =F15 -> 16 | G21: 1 | H21: 1 | I21: 1 | J21: =$I21*($D21-1)*$G21*PRODUCT(H8:H20) -> 0 | K21: =(1-$I21)*($D21-1)*$G21*PRODUCT(H8:H20) -> 0 | L21: =(($D21-1)*$G21+1-$H21)*$I21 -> 0 | M21: =(($D21-1)*$G21+1-$H21)*(1-$I21) -> 0 | N21: =CEILING((P20-H21)/H21+1, 1)*H21-P20 -> 0 | O21: =P20+L21+M21+N21 -> 24000000 | P21: =(O21-G21*(D21-1)-1)/H21+1 -> 24000000 | Q21: =D21*E21*F21 -> 256 | R21: =P21*F21*D21*E21 -> 6144000000 | S21: =R21/$C$4/10^6 -> 2.048
B22: Conv2_7 | C22: Strided Conv 2 | D22: =2*H22 -> 8 | E22: =F21 -> 16 | F22: 32 | G22: 1 | H22: 4 | I22: 1 | J22: =$I22*($D22-1)*$G22*PRODUCT(H8:H21) -> 21 | K22: =(1-$I22)*($D22-1)*$G22*PRODUCT(H8:H21) -> 0 | L22: =(($D22-1)*$G22+1-$H22)*$I22 -> 4 | M22: =(($D22-1)*$G22+1-$H22)*(1-$I22) -> 0 | N22: =CEILING((P21-H22)/H22+1, 1)*H22-P21 -> 0 | O22: =P21+L22+M22+N22 -> 24000004 | P22: =(O22-G22*(D22-1)-1)/H22+1 -> 6000000 | Q22: =D22*E22*F22 -> 4096 | R22: =P22*F22*D22*E22 -> 24576000000 | S22: =R22/$C$4/10^6 -> 8.192
B23: Conv3_1 | C23: Residual Stack 3 | D23: 5 | E23: =F22 -> 32 | F23: =F22 -> 32 | G23: 3 | H23: 1 | I23: 0.5 | J23: =$I23*($D23-1)*$G23*PRODUCT(H8:H22) -> 72 | K23: =(1-$I23)*($D23-1)*$G23*PRODUCT(H8:H22) -> 72 | L23: =(($D23-1)*$G23+1-$H23)*$I23 -> 6 | M23: =(($D23-1)*$G23+1-$H23)*(1-$I23) -> 6 | N23: =CEILING((P22-H23)/H23+1, 1)*H23-P22 -> 0 | O23: =P22+L23+M23+N23 -> 6000012 | P23: =(O23-G23*(D23-1)-1)/H23+1 -> 6000000 | Q23: =D23*E23*F23 -> 5120 | R23: =P23*F23*D23*E23 -> 30720000000 | S23: =R23/$C$4/10^6 -> 10.24
B24: Conv3_2 | C24: Residual Stack 3 | D24: 1 | E24: =F23 -> 32 | F24: =F22 -> 32 | G24: 1 | H24: 1 | I24: 1 | J24: =$I24*($D24-1)*$G24*PRODUCT(H8:H23) -> 0 | K24: =(1-$I24)*($D24-1)*$G24*PRODUCT(H8:H23) -> 0 | L24: =(($D24-1)*$G24+1-$H24)*$I24 -> 0 | M24: =(($D24-1)*$G24+1-$H24)*(1-$I24) -> 0 | N24: =CEILING((P23-H24)/H24+1, 1)*H24-P23 -> 0 | O24: =P23+L24+M24+N24 -> 6000000 | P24: =(O24-G24*(D24-1)-1)/H24+1 -> 6000000 | Q24: =D24*E24*F24 -> 1024 | R24: =P24*F24*D24*E24 -> 6144000000 | S24: =R24/$C$4/10^6 -> 2.048
B25: Conv3_3 | C25: Residual Stack 3 | D25: 5 | E25: =F24 -> 32 | F25: =F22 -> 32 | G25: 7 | H25: 1 | I25: 0.5 | J25: =$I25*($D25-1)*$G25*PRODUCT(H8:H24) -> 168 | K25: =(1-$I25)*($D25-1)*$G25*PRODUCT(H8:H24) -> 168 | L25: =(($D25-1)*$G25+1-$H25)*$I25 -> 14 | M25: =(($D25-1)*$G25+1-$H25)*(1-$I25) -> 14 | N25: =CEILING((P24-H25)/H25+1, 1)*H25-P24 -> 0 | O25: =P24+L25+M25+N25 -> 6000028 | P25: =(O25-G25*(D25-1)-1)/H25+1 -> 6000000 | Q25: =D25*E25*F25 -> 5120 | R25: =P25*F25*D25*E25 -> 30720000000 | S25: =R25/$C$4/10^6 -> 10.24
B26: Conv3_4 | C26: Residual Stack 3 | D26: 1 | E26: =F25 -> 32 | F26: =F22 -> 32 | G26: 1 | H26: 1 | I26: 1 | J26: =$I26*($D26-1)*$G26*PRODUCT(H8:H25) -> 0 | K26: =(1-$I26)*($D26-1)*$G26*PRODUCT(H8:H25) -> 0 | L26: =(($D26-1)*$G26+1-$H26)*$I26 -> 0 | M26: =(($D26-1)*$G26+1-$H26)*(1-$I26) -> 0 | N26: =CEILING((P25-H26)/H26+1, 1)*H26-P25 -> 0 | O26: =P25+L26+M26+N26 -> 6000000 | P26: =(O26-G26*(D26-1)-1)/H26+1 -> 6000000 | Q26: =D26*E26*F26 -> 1024 | R26: =P26*F26*D26*E26 -> 6144000000 | S26: =R26/$C$4/10^6 -> 2.048
B27: Conv3_5 | C27: Residual Stack 3 | D27: 5 | E27: =F26 -> 32 | F27: =F22 -> 32 | G27: 27 | H27: 1 | I27: 1 | J27: =$I27*($D27-1)*$G27*PRODUCT(H8:H26) -> 1296 | K27: =(1-$I27)*($D27-1)*$G27*PRODUCT(H8:H26) -> 0 | L27: =(($D27-1)*$G27+1-$H27)*$I27 -> 108 | M27: =(($D27-1)*$G27+1-$H27)*(1-$I27) -> 0 | N27: =CEILING((P26-H27)/H27+1, 1)*H27-P26 -> 0 | O27: =P26+L27+M27+N27 -> 6000108 | P27: =(O27-G27*(D27-1)-1)/H27+1 -> 6000000 | Q27: =D27*E27*F27 -> 5120 | R27: =P27*F27*D27*E27 -> 30720000000 | S27: =R27/$C$4/10^6 -> 10.24
B28: Conv3_6 | C28: Residual Stack 3 | D28: 1 | E28: =F27 -> 32 | F28: =F22 -> 32 | G28: 1 | H28: 1 | I28: 1 | J28: =$I28*($D28-1)*$G28*PRODUCT(H8:H27) -> 0 | K28: =(1-$I28)*($D28-1)*$G28*PRODUCT(H8:H27) -> 0 | L28: =(($D28-1)*$G28+1-$H28)*$I28 -> 0 | M28: =(($D28-1)*$G28+1-$H28)*(1-$I28) -> 0 | N28: =CEILING((P27-H28)/H28+1, 1)*H28-P27 -> 0 | O28: =P27+L28+M28+N28 -> 6000000 | P28: =(O28-G28*(D28-1)-1)/H28+1 -> 6000000 | Q28: =D28*E28*F28 -> 1024 | R28: =P28*F28*D28*E28 -> 6144000000 | S28: =R28/$C$4/10^6 -> 2.048
B29: Conv3_7 | C29: Strided Conv 3 | D29: =2*H29 -> 8 | E29: =F28 -> 32 | F29: 64 | G29: 1 | H29: 4 | I29: 1 | J29: =$I29*($D29-1)*$G29*PRODUCT(H8:H28) -> 84 | K29: =(1-$I29)*($D29-1)*$G29*PRODUCT(H8:H28) -> 0 | L29: =(($D29-1)*$G29+1-$H29)*$I29 -> 4 | M29: =(($D29-1)*$G29+1-$H29)*(1-$I29) -> 0 | N29: =CEILING((P28-H29)/H29+1, 1)*H29-P28 -> 0 | O29: =P28+L29+M29+N29 -> 6000004 | P29: =(O29-G29*(D29-1)-1)/H29+1 -> 1500000 | Q29: =D29*E29*F29 -> 16384 | R29: =P29*F29*D29*E29 -> 24576000000 | S29: =R29/$C$4/10^6 -> 8.192
B30: Conv4_1 | C30: Residual Stack 4 | D30: 5 | E30: =F29 -> 64 | F30: =F29 -> 64 | G30: 3 | H30: 1 | I30: 1 | J30: =$I30*($D30-1)*$G30*PRODUCT(H8:H29) -> 576 | K30: =(1-$I30)*($D30-1)*$G30*PRODUCT(H8:H29) -> 0 | L30: =(($D30-1)*$G30+1-$H30)*$I30 -> 12 | M30: =(($D30-1)*$G30+1-$H30)*(1-$I30) -> 0 | N30: =CEILING((P29-H30)/H30+1, 1)*H30-P29 -> 0 | O30: =P29+L30+M30+N30 -> 1500012 | P30: =(O30-G30*(D30-1)-1)/H30+1 -> 1500000 | Q30: =D30*E30*F30 -> 20480 | R30: =P30*F30*D30*E30 -> 30720000000 | S30: =R30/$C$4/10^6 -> 10.24
B31: Conv4_2 | C31: Residual Stack 4 | D31: 1 | E31: =F30 -> 64 | F31: =F29 -> 64 | G31: 1 | H31: 1 | I31: 1 | J31: =$I31*($D31-1)*$G31*PRODUCT(H8:H30) -> 0 | K31: =(1-$I31)*($D31-1)*$G31*PRODUCT(H8:H30) -> 0 | L31: =(($D31-1)*$G31+1-$H31)*$I31 -> 0 | M31: =(($D31-1)*$G31+1-$H31)*(1-$I31) -> 0 | N31: =CEILING((P30-H31)/H31+1, 1)*H31-P30 -> 0 | O31: =P30+L31+M31+N31 -> 1500000 | P31: =(O31-G31*(D31-1)-1)/H31+1 -> 1500000 | Q31: =D31*E31*F31 -> 4096 | R31: =P31*F31*D31*E31 -> 6144000000 | S31: =R31/$C$4/10^6 -> 2.048
B32: Conv4_3 | C32: Residual Stack 4 | D32: 7 | E32: =F31 -> 64 | F32: =F29 -> 64 | G32: 9 | H32: 1 | I32: 1 | J32: =$I32*($D32-1)*$G32*PRODUCT(H8:H31) -> 2592 | K32: =(1-$I32)*($D32-1)*$G32*PRODUCT(H8:H31) -> 0 | L32: =(($D32-1)*$G32+1-$H32)*$I32 -> 54 | M32: =(($D32-1)*$G32+1-$H32)*(1-$I32) -> 0 | N32: =CEILING((P31-H32)/H32+1, 1)*H32-P31 -> 0 | O32: =P31+L32+M32+N32 -> 1500054 | P32: =(O32-G32*(D32-1)-1)/H32+1 -> 1500000 | Q32: =D32*E32*F32 -> 28672 | R32: =P32*F32*D32*E32 -> 43008000000 | S32: =R32/$C$4/10^6 -> 14.336
B33: Conv4_4 | C33: Residual Stack 4 | D33: 3 | E33: =F32 -> 64 | F33: =F29 -> 64 | G33: 1 | H33: 1 | I33: 1 | J33: =$I33*($D33-1)*$G33*PRODUCT(H8:H32) -> 96 | K33: =(1-$I33)*($D33-1)*$G33*PRODUCT(H8:H32) -> 0 | L33: =(($D33-1)*$G33+1-$H33)*$I33 -> 2 | M33: =(($D33-1)*$G33+1-$H33)*(1-$I33) -> 0 | N33: =CEILING((P32-H33)/H33+1, 1)*H33-P32 -> 0 | O33: =P32+L33+M33+N33 -> 1500002 | P33: =(O33-G33*(D33-1)-1)/H33+1 -> 1500000 | Q33: =D33*E33*F33 -> 12288 | R33: =P33*F33*D33*E33 -> 18432000000 | S33: =R33/$C$4/10^6 -> 6.144
B34: Conv4_5 | C34: Residual Stack 4 | D34: 7 | E34: =F33 -> 64 | F34: =F29 -> 64 | G34: 27 | H34: 1 | I34: 1 | J34: =$I34*($D34-1)*$G34*PRODUCT(H8:H33) -> 7776 | K34: =(1-$I34)*($D34-1)*$G34*PRODUCT(H8:H33) -> 0 | L34: =(($D34-1)*$G34+1-$H34)*$I34 -> 162 | M34: =(($D34-1)*$G34+1-$H34)*(1-$I34) -> 0 | N34: =CEILING((P33-H34)/H34+1, 1)*H34-P33 -> 0 | O34: =P33+L34+M34+N34 -> 1500162 | P34: =(O34-G34*(D34-1)-1)/H34+1 -> 1500000 | Q34: =D34*E34*F34 -> 28672 | R34: =P34*F34*D34*E34 -> 43008000000 | S34: =R34/$C$4/10^6 -> 14.336
B35: Conv4_6 | C35: Residual Stack 4 | D35: 3 | E35: =F34 -> 64 | F35: =F29 -> 64 | G35: 1 | H35: 1 | I35: 1 | J35: =$I35*($D35-1)*$G35*PRODUCT(H8:H34) -> 96 | K35: =(1-$I35)*($D35-1)*$G35*PRODUCT(H8:H34) -> 0 | L35: =(($D35-1)*$G35+1-$H35)*$I35 -> 2 | M35: =(($D35-1)*$G35+1-$H35)*(1-$I35) -> 0 | N35: =CEILING((P34-H35)/H35+1, 1)*H35-P34 -> 0 | O35: =P34+L35+M35+N35 -> 1500002 | P35: =(O35-G35*(D35-1)-1)/H35+1 -> 1500000 | Q35: =D35*E35*F35 -> 12288 | R35: =P35*F35*D35*E35 -> 18432000000 | S35: =R35/$C$4/10^6 -> 6.144
B36: Conv4_7 | C36: Strided Conv 4 | D36: =2*H36 -> 10 | E36: =F35 -> 64 | F36: 160 | G36: 1 | H36: 5 | I36: 1 | J36: =$I36*($D36-1)*$G36*PRODUCT(H8:H35) -> 432 | K36: =(1-$I36)*($D36-1)*$G36*PRODUCT(H8:H35) -> 0 | L36: =(($D36-1)*$G36+1-$H36)*$I36 -> 5 | M36: =(($D36-1)*$G36+1-$H36)*(1-$I36) -> 0 | N36: =CEILING((P35-H36)/H36+1, 1)*H36-P35 -> 0 | O36: =P35+L36+M36+N36 -> 1500005 | P36: =(O36-G36*(D36-1)-1)/H36+1 -> 300000 | Q36: =D36*E36*F36 -> 102400 | R36: =P36*F36*D36*E36 -> 30720000000 | S36: =R36/$C$4/10^6 -> 10.24
B38: FOV: | C38: Field of View (also known as receptive field) | M38: Overall stride | N38: Overall FOV left | O38: Overall FOV right | P38: Total FOV | Q38: Total #Params | R38: Total MACs | S38: Total MFLOPs
B39: alignment: | C39: Indicates how the convolution kernel is aligned: | M39: =PRODUCT(H8:H36) -> 240 | N39: =SUM(J8:J36) -> 13844 | O39: =SUM(K8:K36) -> 240 | P39: =SUM(N39:O39)+1 -> 14085 | Q39: =SUM(Q8:Q36) -> 254392 | R39: =SUM(R8:R36) -> 566208000000 | S39: =SUM(S8:S36)*2 -> 377.472
C40: 1 | D40: right-aligned, no latency is introduced
C41: 0 | D41: left-aligned
C42: 0.5 | D42: centre-aligned
B43: extra-padding-right: | C43: A padding applied in offline processing to make sure that no input samples are discarded and input and output audio are of the same length
C44: It is not relevant in online streaming operation
...

Sheet VQ-Track1
B3: Embedding Dimension | C3: Projection Dimension | D3: Codebook Size | E3: #Layers | F3: Frame Rate | G3: MMAC/s - Input Projections | H3: MMAC/s-Distance Calculation | I3: MMAC/s-Output Projection | J3: Total MFLOPS | K3: Total MFLOPS w/o OP
B4: 160 | C4: 12 | D4: 1024 | E4: 6 | F4: 100 | G4: =F4*B4*C4*E4/10^6 -> 1.152 | H4: =F4*C4*D4*E4/10^6 -> 7.3728 | I4: =F4*C4*B4*E4/10^6 -> 1.152 | J4: =SUM(G4:I4)*2 -> 19.3536 | K4: =SUM(G4:H4)*2 -> 17.0496
B7: Total MFLOPS w/o OP: | C7: Total Computational Complexity in MFLOPS without output projections.
C8: Note that output projections can be optimized out after training by applying them to the codewords and storing two separate codebooks, one for transmit side and one for receive side, with the downside of increasing binary size

Sheet Decoder-Track1
B3: Input Length (frames) | C3: 300000
B4: Frame rate (Hz) | C4: 100
B5: Duration (sec) | C5: =C3/C4 -> 3000
B6: Input Dimension | C6: 160
B7: Samples Per Frame | C7: 240
B9: Layer Name | C9: block ID | D9: kernel Size | E9: input channels | F9: output channels | G9: dilation | H9: stride | I9: alignment | J9: FOV left (in frames) | K9: FOV right (in frames) | L9: padding left | M9: padding right | N9: extra padding right | O9: padded input length | P9: output length | Q9: #Params | R9: #MAC | S9: MMAC/s
B10: TransposedConv1 | C10: Upsampling 1 | D10: =H10 -> 5 | E10: =C6 -> 160 | F10: 64 | G10: 1 | H10: 5 | I10: 1 | J10: =($D10-$H10)*(1-$I10) -> 0 | K10: =($D10-$H10)*$I10 -> 0 | L10: =($D10-$H10)*$I10 -> 0 | M10: =($D10-$H10)*(1-$I10) -> 0 | N10: 0 | O10: =C3 -> 300000 | P10: =($C$3-1)*H10+G10*(D10-1)+1+L10+M10 -> 1500000 | Q10: =D10*E10*F10 -> 51200 | R10: =C3*D10*E10*F10 -> 15360000000 | S10: =R10/$C$5/10^6 -> 5.12
B11: Conv1_1 | C11: ResidualStack1 | D11: 3 | E11: =F10 -> 64 | F11: =F10 -> 64 | G11: 5 | H11: 1 | I11: 0.5 | J11: =$I11*($D11-1)*$G11/$H$10 -> 1 | K11: =(1-$I11)*($D11-1)*$G11/$H$10 -> 1 | L11: =(($D11-1)*$G11+1-$H11)*$I11 -> 5 | M11: =(($D11-1)*$G11+1-$H11)*(1-$I11) -> 5 | N11: =CEILING((P10-H11)/H11+1, 1)*H11-P10 -> 0 | O11: =P10+L11+M11+N11 -> 1500010 | P11: =O11-G11*(D11-1) -> 1500000 | Q11: =D11*E11*F11 -> 12288 | R11: =P11*D11*E11*F11 -> 18432000000 | S11: =R11/$C$5/10^6 -> 6.144
B12: Conv1_2 | C12: ResidualStack1 | D12: 1 | E12: =F11 -> 64 | F12: =F10 -> 64 | G12: 1 | H12: 1 | I12: 1 | J12: =$I12*($D12-1)*$G12/$H$10 -> 0 | K12: =(1-$I12)*($D12-1)*$G12/$H$10 -> 0 | L12: =(($D12-1)*$G12+1-$H12)*$I12 -> 0 | M12: =(($D12-1)*$G12+1-$H12)*(1-$I12) -> 0 | N12: =CEILING((P11-H12)/H12+1, 1)*H12-P11 -> 0 | O12: =P11+L12+M12+N12 -> 1500000 | P12: =O12-G12*(D12-1) -> 1500000 | Q12: =D12*E12*F12 -> 4096 | R12: =P12*D12*E12*F12 -> 6144000000 | S12: =R12/$C$5/10^6 -> 2.048
B13: Conv1_3 | C13: ResidualStack1 | D13: 5 | E13: =F12 -> 64 | F13: =F10 -> 64 | G13: 5 | H13: 1 | I13: 1 | J13: =$I13*($D13-1)*$G13/$H$10 -> 4 | K13: =(1-$I13)*($D13-1)*$G13/$H$10 -> 0 | L13: =(($D13-1)*$G13+1-$H13)*$I13 -> 20 | M13: =(($D13-1)*$G13+1-$H13)*(1-$I13) -> 0 | N13: =CEILING((P12-H13)/H13+1, 1)*H13-P12 -> 0 | O13: =P12+L13+M13+N13 -> 1500020 | P13: =O13-G13*(D13-1) -> 1500000 | Q13: =D13*E13*F13 -> 20480 | R13: =P13*D13*E13*F13 -> 30720000000 | S13: =R13/$C$5/10^6 -> 10.24
B14: Conv1_4 | C14: ResidualStack1 | D14: 1 | E14: =F13 -> 64 | F14: =F10 -> 64 | G14: 1 | H14: 1 | I14: 1 | J14: =$I14*($D14-1)*$G14/$H$10 -> 0 | K14: =(1-$I14)*($D14-1)*$G14/$H$10 -> 0 | L14: =(($D14-1)*$G14+1-$H14)*$I14 -> 0 | M14: =(($D14-1)*$G14+1-$H14)*(1-$I14) -> 0 | N14: =CEILING((P13-H14)/H14+1, 1)*H14-P13 -> 0 | O14: =P13+L14+M14+N14 -> 1500000 | P14: =O14-G14*(D14-1) -> 1500000 | Q14: =D14*E14*F14 -> 4096 | R14: =P14*D14*E14*F14 -> 6144000000 | S14: =R14/$C$5/10^6 -> 2.048
B15: Conv1_5 | C15: ResidualStack1 | D15: 5 | E15: =F14 -> 64 | F15: =F10 -> 64 | G15: 25 | H15: 1 | I15: 1 | J15: =$I15*($D15-1)*$G15/$H$10 -> 20 | K15: =(1-$I15)*($D15-1)*$G15/$H$10 -> 0 | L15: =(($D15-1)*$G15+1-$H15)*$I15 -> 100 | M15: =(($D15-1)*$G15+1-$H15)*(1-$I15) -> 0 | N15: =CEILING((P14-H15)/H15+1, 1)*H15-P14 -> 0 | O15: =P14+L15+M15+N15 -> 1500100 | P15: =O15-G15*(D15-1) -> 1500000 | Q15: =D15*E15*F15 -> 20480 | R15: =P15*D15*E15*F15 -> 30720000000 | S15: =R15/$C$5/10^6 -> 10.24
B16: Conv1_6 | C16: ResidualStack1 | D16: 3 | E16: =F15 -> 64 | F16: =F10 -> 64 | G16: 1 | H16: 1 | I16: 1 | J16: =$I16*($D16-1)*$G16/$H$10 -> 0.4 | K16: =(1-$I16)*($D16-1)*$G16/$H$10 -> 0 | L16: =(($D16-1)*$G16+1-$H16)*$I16 -> 2 | M16: =(($D16-1)*$G16+1-$H16)*(1-$I16) -> 0 | N16: =CEILING((P15-H16)/H16+1, 1)*H16-P15 -> 0 | O16: =P15+L16+M16+N16 -> 1500002 | P16: =O16-G16*(D16-1) -> 1500000 | Q16: =D16*E16*F16 -> 12288 | R16: =P16*D16*E16*F16 -> 18432000000 | S16: =R16/$C$5/10^6 -> 6.144
B17: TransposedConv2 | C17: Upsampling 2 | D17: =H17 -> 4 | E17: =F16 -> 64 | F17: 32 | G17: 1 | H17: 4 | I17: 1 | J17: =($D17-$H17)*(1-$I17) -> 0 | K17: =($D17-$H17)*$I17 -> 0 | L17: =($D17-$H17)*$I17 -> 0 | M17: =($D17-$H17)*(1-$I17) -> 0 | N17: 0 | O17: =P16 -> 1500000 | P17: =(P16-1)*H17+G17*(D17-1)+1 -> 6000000 | Q17: =D17*E17*F17 -> 8192 | R17: =P16*D17*E17*F17 -> 12288000000 | S17: =R17/$C$5/10^6 -> 4.096
B18: Conv2_1 | C18: ResidualStack2 | D18: 5 | E18: =F17 -> 32 | F18: =F17 -> 32 | G18: 4 | H18: 1 | I18: 1 | J18: =$I18*($D18-1)*$G18/$H$17/$H$10 -> 0.8 | K18: =(1-$I18)*($D18-1)*$G18/$H$17/$H$10 -> 0 | L18: =(($D18-1)*$G18+1-$H18)*$I18 -> 16 | M18: =(($D18-1)*$G18+1-$H18)*(1-$I18) -> 0 | N18: =CEILING((P17-H18)/H18+1, 1)*H18-P17 -> 0 | O18: =P17+L18+M18+N18 -> 6000016 | P18: =O18-G18*(D18-1) -> 6000000 | Q18: =D18*E18*F18 -> 5120 | R18: =P18*D18*E18*F18 -> 30720000000 | S18: =R18/$C$5/10^6 -> 10.24
B19: Conv2_2 | C19: ResidualStack2 | D19: 1 | E19: =F18 -> 32 | F19: =F17 -> 32 | G19: 1 | H19: 1 | I19: 1 | J19: =$I19*($D19-1)*$G19/$H$17/$H$10 -> 0 | K19: =(1-$I19)*($D19-1)*$G19/$H$17/$H$10 -> 0 | L19: =(($D19-1)*$G19+1-$H19)*$I19 -> 0 | M19: =(($D19-1)*$G19+1-$H19)*(1-$I19) -> 0 | N19: =CEILING((P18-H19)/H19+1, 1)*H19-P18 -> 0 | O19: =P18+L19+M19+N19 -> 6000000 | P19: =O19-G19*(D19-1) -> 6000000 | Q19: =D19*E19*F19 -> 1024 | R19: =P19*D19*E19*F19 -> 6144000000 | S19: =R19/$C$5/10^6 -> 2.048
B20: Conv2_3 | C20: ResidualStack2 | D20: 5 | E20: =F19 -> 32 | F20: =F17 -> 32 | G20: 5 | H20: 1 | I20: 1 | J20: =$I20*($D20-1)*$G20/$H$17/$H$10 -> 1 | K20: =(1-$I20)*($D20-1)*$G20/$H$17/$H$10 -> 0 | L20: =(($D20-1)*$G20+1-$H20)*$I20 -> 20 | M20: =(($D20-1)*$G20+1-$H20)*(1-$I20) -> 0 | N20: =CEILING((P19-H20)/H20+1, 1)*H20-P19 -> 0 | O20: =P19+L20+M20+N20 -> 6000020 | P20: =O20-G20*(D20-1) -> 6000000 | Q20: =D20*E20*F20 -> 5120 | R20: =P20*D20*E20*F20 -> 30720000000 | S20: =R20/$C$5/10^6 -> 10.24
B21: Conv2_4 | C21: ResidualStack2 | D21: 1 | E21: =F20 -> 32 | F21: =F17 -> 32 | G21: 1 | H21: 1 | I21: 1 | J21: =$I21*($D21-1)*$G21/$H$17/$H$10 -> 0 | K21: =(1-$I21)*($D21-1)*$G21/$H$17/$H$10 -> 0 | L21: =(($D21-1)*$G21+1-$H21)*$I21 -> 0 | M21: =(($D21-1)*$G21+1-$H21)*(1-$I21) -> 0 | N21: =CEILING((P20-H21)/H21+1, 1)*H21-P20 -> 0 | O21: =P20+L21+M21+N21 -> 6000000 | P21: =O21-G21*(D21-1) -> 6000000 | Q21: =D21*E21*F21 -> 1024 | R21: =P21*D21*E21*F21 -> 6144000000 | S21: =R21/$C$5/10^6 -> 2.048
B22: Conv2_5 | C22: ResidualStack2 | D22: 5 | E22: =F21 -> 32 | F22: =F17 -> 32 | G22: 25 | H22: 1 | I22: 1 | J22: =$I22*($D22-1)*$G22/$H$17/$H$10 -> 5 | K22: =(1-$I22)*($D22-1)*$G22/$H$17/$H$10 -> 0 | L22: =(($D22-1)*$G22+1-$H22)*$I22 -> 100 | M22: =(($D22-1)*$G22+1-$H22)*(1-$I22) -> 0 | N22: =CEILING((P21-H22)/H22+1, 1)*H22-P21 -> 0 | O22: =P21+L22+M22+N22 -> 6000100 | P22: =O22-G22*(D22-1) -> 6000000 | Q22: =D22*E22*F22 -> 5120 | R22: =P22*D22*E22*F22 -> 30720000000 | S22: =R22/$C$5/10^6 -> 10.24
B23: Conv2_6 | C23: ResidualStack2 | D23: 1 | E23: =F22 -> 32 | F23: =F17 -> 32 | G23: 1 | H23: 1 | I23: 1 | J23: =$I23*($D23-1)*$G23/$H$17/$H$10 -> 0 | K23: =(1-$I23)*($D23-1)*$G23/$H$17/$H$10 -> 0 | L23: =(($D23-1)*$G23+1-$H23)*$I23 -> 0 | M23: =(($D23-1)*$G23+1-$H23)*(1-$I23) -> 0 | N23: =CEILING((P22-H23)/H23+1, 1)*H23-P22 -> 0 | O23: =P22+L23+M23+N23 -> 6000000 | P23: =O23-G23*(D23-1) -> 6000000 | Q23: =D23*E23*F23 -> 1024 | R23: =P23*D23*E23*F23 -> 6144000000 | S23: =R23/$C$5/10^6 -> 2.048
B24: TransposedConv3 | C24: Upsampling 3 | D24: =H24 -> 3 | E24: =F23 -> 32 | F24: 16 | G24: 1 | H24: 3 | I24: 1 | J24: =($D24-$H24)*(1-$I24) -> 0 | K24: =($D24-$H24)*(1-$I24) -> 0 | L24: =($D24-$H24)*$I24 -> 0 | M24: =($D24-$H24)*(1-$I24) -> 0 | N24: 0 | O24: =P23+L24+M24+N24 -> 6000000 | P24: =(P23-1)*H24+G24*(D24-1)+1 -> 18000000 | Q24: =D24*E24*F24 -> 1536 | R24: =P23*D24*E24*F24 -> 9216000000 | S24: =R24/$C$5/10^6 -> 3.072
B25: Conv3_1 | C25: ResidualStack3 | D25: 5 | E25: =F24 -> 16 | F25: =F24 -> 16 | G25: 3 | H25: 1 | I25: 1 | J25: =$I25*($D25-1)*$G25/$H$24/$H$17/$H$10 -> 0.2 | K25: =(1-$I25)*($D25-1)*$G25/$H$24/$H$17/$H$10 -> 0 | L25: =(($D25-1)*$G25+1-$H25)*$I25 -> 12 | M25: =(($D25-1)*$G25+1-$H25)*(1-$I25) -> 0 | N25: =CEILING((P24-H25)/H25+1, 1)*H25-P24 -> 0 | O25: =P24+L25+M25+N25 -> 18000012 | P25: =O25-G25*(D25-1) -> 18000000 | Q25: =D25*E25*F25 -> 1280 | R25: =P25*D25*E25*F25 -> 23040000000 | S25: =R25/$C$5/10^6 -> 7.68
B26: Conv3_2 | C26: ResidualStack3 | D26: 1 | E26: =F25 -> 16 | F26: =F24 -> 16 | G26: 1 | H26: 1 | I26: 1 | J26: =$I26*($D26-1)*$G26/$H$24/$H$17/$H$10 -> 0 | K26: =(1-$I26)*($D26-1)*$G26/$H$24/$H$17/$H$10 -> 0 | L26: =(($D26-1)*$G26+1-$H26)*$I26 -> 0 | M26: =(($D26-1)*$G26+1-$H26)*(1-$I26) -> 0 | N26: =CEILING((P25-H26)/H26+1, 1)*H26-P25 -> 0 | O26: =P25+L26+M26+N26 -> 18000000 | P26: =O26-G26*(D26-1) -> 18000000 | Q26: =D26*E26*F26 -> 256 | R26: =P26*D26*E26*F26 -> 4608000000 | S26: =R26/$C$5/10^6 -> 1.536
B27: Conv3_3 | C27: ResidualStack3 | D27: 5 | E27: =F26 -> 16 | F27: =F24 -> 16 | G27: 5 | H27: 1 | I27: 1 | J27: =$I27*($D27-1)*$G27/$H$24/$H$17/$H$10 -> 0.33333333 | K27: =(1-$I27)*($D27-1)*$G27/$H$24/$H$17/$H$10 -> 0 | L27: =(($D27-1)*$G27+1-$H27)*$I27 -> 20 | M27: =(($D27-1)*$G27+1-$H27)*(1-$I27) -> 0 | N27: =CEILING((P26-H27)/H27+1, 1)*H27-P26 -> 0 | O27: =P26+L27+M27+N27 -> 18000020 | P27: =O27-G27*(D27-1) -> 18000000 | Q27: =D27*E27*F27 -> 1280 | R27: =P27*D27*E27*F27 -> 23040000000 | S27: =R27/$C$5/10^6 -> 7.68
B28: Conv3_4 | C28: ResidualStack3 | D28: 1 | E28: =F27 -> 16 | F28: =F24 -> 16 | G28: 1 | H28: 1 | I28: 1 | J28: =$I28*($D28-1)*$G28/$H$24/$H$17/$H$10 -> 0 | K28: =(1-$I28)*($D28-1)*$G28/$H$24/$H$17/$H$10 -> 0 | L28: =(($D28-1)*$G28+1-$H28)*$I28 -> 0 | M28: =(($D28-1)*$G28+1-$H28)*(1-$I28) -> 0 | N28: =CEILING((P27-H28)/H28+1, 1)*H28-P27 -> 0 | O28: =P27+L28+M28+N28 -> 18000000 | P28: =O28-G28*(D28-1) -> 18000000 | Q28: =D28*E28*F28 -> 256 | R28: =P28*D28*E28*F28 -> 4608000000 | S28: =R28/$C$5/10^6 -> 1.536
B29: Conv3_5 | C29: ResidualStack3 | D29: 5 | E29: =F28 -> 16 | F29: =F24 -> 16 | G29: 25 | H29: 1 | I29: 1 | J29: =$I29*($D29-1)*$G29/$H$24/$H$17/$H$10 -> 1.6666667 | K29: =(1-$I29)*($D29-1)*$G29/$H$24/$H$17/$H$10 -> 0 | L29: =(($D29-1)*$G29+1-$H29)*$I29 -> 100 | M29: =(($D29-1)*$G29+1-$H29)*(1-$I29) -> 0 | N29: =CEILING((P28-H29)/H29+1, 1)*H29-P28 -> 0 | O29: =P28+L29+M29+N29 -> 18000100 | P29: =O29-G29*(D29-1) -> 18000000 | Q29: =D29*E29*F29 -> 1280 | R29: =P29*D29*E29*F29 -> 23040000000 | S29: =R29/$C$5/10^6 -> 7.68
B30: Conv3_6 | C30: ResidualStack3 | D30: 1 | E30: =F29 -> 16 | F30: =F24 -> 16 | G30: 1 | H30: 1 | I30: 1 | J30: =$I30*($D30-1)*$G30/$H$24/$H$17/$H$10 -> 0 | K30: =(1-$I30)*($D30-1)*$G30/$H$24/$H$17/$H$10 -> 0 | L30: =(($D30-1)*$G30+1-$H30)*$I30 -> 0 | M30: =(($D30-1)*$G30+1-$H30)*(1-$I30) -> 0 | N30: =CEILING((P29-H30)/H30+1, 1)*H30-P29 -> 0 | O30: =P29+L30+M30+N30 -> 18000000 | P30: =O30-G30*(D30-1) -> 18000000 | Q30: =D30*E30*F30 -> 256 | R30: =P30*D30*E30*F30 -> 4608000000 | S30: =R30/$C$5/10^6 -> 1.536
B31: TransposedConv4 | C31: Upsampling 4 | D31: =H31 -> 4 | E31: =F30 -> 16 | F31: 8 | G31: 1 | H31: 4 | I31: 1 | J31: =($D31-$H31)*(1-$I31) -> 0 | K31: =($D31-$H31)*$I31 -> 0 | L31: =($D31-$H31)*$I31 -> 0 | M31: =($D31-$H31)*(1-$I31) -> 0 | N31: 0 | O31: =P30 -> 18000000 | P31: =(P30-1)*H31+G31*(D31-1)+1 -> 72000000 | Q31: =D31*E31*F31 -> 512 | R31: =P30*D31*E31*F31 -> 9216000000 | S31: =R31/$C$5/10^6 -> 3.072
B32: Conv4_1 | C32: ResidualStack4 | D32: 5 | E32: =F31 -> 8 | F32: =F31 -> 8 | G32: 4 | H32: 1 | I32: 1 | J32: =$I32*($D32-1)*$G32/$H$31/$H$24/$H$17/$H$10 -> 0.066666667 | K32: =(1-$I32)*($D32-1)*$G32/$H$31/$H$24/$H$17/$H$10 -> 0 | L32: =(($D32-1)*$G32+1-$H32)*$I32 -> 16 | M32: =(($D32-1)*$G32+1-$H32)*(1-$I32) -> 0 | N32: =CEILING((P31-H32)/H32+1, 1)*H32-P31 -> 0 | O32: =P31+L32+M32+N32 -> 72000016 | P32: =O32-G32*(D32-1) -> 72000000 | Q32: =D32*E32*F32 -> 320 | R32: =P32*D32*E32*F32 -> 23040000000 | S32: =R32/$C$5/10^6 -> 7.68
B33: Conv4_2 | C33: ResidualStack4 | D33: 1 | E33: =F32 -> 8 | F33: =F31 -> 8 | G33: 1 | H33: 1 | I33: 1 | J33: =$I33*($D33-1)*$G33/$H$31/$H$24/$H$17/$H$10 -> 0 | K33: =(1-$I33)*($D33-1)*$G33/$H$31/$H$24/$H$17/$H$10 -> 0 | L33: =(($D33-1)*$G33+1-$H33)*$I33 -> 0 | M33: =(($D33-1)*$G33+1-$H33)*(1-$I33) -> 0 | N33: =CEILING((P32-H33)/H33+1, 1)*H33-P32 -> 0 | O33: =P32+L33+M33+N33 -> 72000000 | P33: =O33-G33*(D33-1) -> 72000000 | Q33: =D33*E33*F33 -> 64 | R33: =P33*D33*E33*F33 -> 4608000000 | S33: =R33/$C$5/10^6 -> 1.536
B34: Conv4_3 | C34: ResidualStack4 | D34: 5 | E34: =F33 -> 8 | F34: =F31 -> 8 | G34: 5 | H34: 1 | I34: 1 | J34: =$I34*($D34-1)*$G34/$H$31/$H$24/$H$17/$H$10 -> 0.083333333 | K34: =(1-$I34)*($D34-1)*$G34/$H$31/$H$24/$H$17/$H$10 -> 0 | L34: =(($D34-1)*$G34+1-$H34)*$I34 -> 20 | M34: =(($D34-1)*$G34+1-$H34)*(1-$I34) -> 0 | N34: =CEILING((P33-H34)/H34+1, 1)*H34-P33 -> 0 | O34: =P33+L34+M34+N34 -> 72000020 | P34: =O34-G34*(D34-1) -> 72000000 | Q34: =D34*E34*F34 -> 320 | R34: =P34*D34*E34*F34 -> 23040000000 | S34: =R34/$C$5/10^6 -> 7.68
B35: Conv4_4 | C35: ResidualStack4 | D35: 1 | E35: =F34 -> 8 | F35: =F31 -> 8 | G35: 1 | H35: 1 | I35: 1 | J35: =$I35*($D35-1)*$G35/$H$31/$H$24/$H$17/$H$10 -> 0 | K35: =(1-$I35)*($D35-1)*$G35/$H$31/$H$24/$H$17/$H$10 -> 0 | L35: =(($D35-1)*$G35+1-$H35)*$I35 -> 0 | M35: =(($D35-1)*$G35+1-$H35)*(1-$I35) -> 0 | N35: =CEILING((P34-H35)/H35+1, 1)*H35-P34 -> 0 | O35: =P34+L35+M35+N35 -> 72000000 | P35: =O35-G35*(D35-1) -> 72000000 | Q35: =D35*E35*F35 -> 64 | R35: =P35*D35*E35*F35 -> 4608000000 | S35: =R35/$C$5/10^6 -> 1.536
B36: Conv4_5 | C36: ResidualStack4 | D36: 5 | E36: =F35 -> 8 | F36: =F31 -> 8 | G36: 25 | H36: 1 | I36: 1 | J36: =$I36*($D36-1)*$G36/$H$31/$H$24/$H$17/$H$10 -> 0.41666667 | K36: =(1-$I36)*($D36-1)*$G36/$H$31/$H$24/$H$17/$H$10 -> 0 | L36: =(($D36-1)*$G36+1-$H36)*$I36 -> 100 | M36: =(($D36-1)*$G36+1-$H36)*(1-$I36) -> 0 | N36: =CEILING((P35-H36)/H36+1, 1)*H36-P35 -> 0 | O36: =P35+L36+M36+N36 -> 72000100 | P36: =O36-G36*(D36-1) -> 72000000 | Q36: =D36*E36*F36 -> 320 | R36: =P36*D36*E36*F36 -> 23040000000 | S36: =R36/$C$5/10^6 -> 7.68
B37: Conv4_6 | C37: ResidualStack4 | D37: 1 | E37: =F36 -> 8 | F37: =F31 -> 8 | G37: 1 | H37: 1 | I37: 1 | J37: =$I37*($D37-1)*$G37/$H$31/$H$24/$H$17/$H$10 -> 0 | K37: =(1-$I37)*($D37-1)*$G37/$H$31/$H$24/$H$17/$H$10 -> 0 | L37: =(($D37-1)*$G37+1-$H37)*$I37 -> 0 | M37: =(($D37-1)*$G37+1-$H37)*(1-$I37) -> 0 | N37: =CEILING((P36-H37)/H37+1, 1)*H37-P36 -> 0 | O37: =P36+L37+M37+N37 -> 72000000 | P37: =O37-G37*(D37-1) -> 72000000 | Q37: =D37*E37*F37 -> 64 | R37: =P37*D37*E37*F37 -> 4608000000 | S37: =R37/$C$5/10^6 -> 1.536
B38: Final Conv | D38: 21 | E38: =F37 -> 8 | F38: 1 | G38: 1 | H38: 1 | I38: 1 | J38: =$I38*($D38-1)*$G38/$H$31/$H$24/$H$17/$H$10 -> 0.083333333 | K38: =(1-$I38)*($D38-1)*$G38/$H$31/$H$24/$H$17/$H$10 -> 0 | L38: =(($D38-1)*$G38+1-$H38)*$I38 -> 20 | M38: =(($D38-1)*$G38+1-$H38)*(1-$I38) -> 0 | N38: =CEILING((P37-H38)/H38+1, 1)*H38-P37 -> 0 | O38: =P37+L38+M38+N38 -> 72000020 | P38: =O38-G38*(D38-1) -> 72000000 | Q38: =D38*E38*F38 -> 168 | R38: =P38*D38*E38*F38 -> 12096000000 | S38: =R38/$C$5/10^6 -> 4.032
B41: FOV: | C41: Field of View (also known as receptive field) | M41: Overall stride | N41: Overall FOV left ( samples) | O41: Overall FOV right (samples) | P41: Total FOV | Q41: Total #Params | R41: Total MACs | S41: Total MFLOPs
B42: alignment for convolution: | C42: Indicates how the convolution kernel is aligned: | M42: =PRODUCT(H10:H38) -> 240 | N42: =SUM(J10:J38)*C7 -> 8412 | O42: =SUM(K10:K38)*C7 -> 240 | P42: =SUM(N42:O42) -> 8652 | Q42: =SUM(Q10:Q38) -> 159528 | R42: =SUM(S10:S38) -> 148.416 | S42: =R42*2 -> 296.832
C43: 1 | D43: right-aligned, no latency is introduced
C44: 0 | D44: left-aligned
C45: 0.5 | D45: centre-aligned
...

Sheet Summary-Track1
B2: COMPUTATIONAL COMPLEXITY
C4: Baseline Model | D4: LRAC Challenge Budget
B5: Transmit Side Compute (MFLOPS) | C5: ='Encoder-Track1'!S39+'VQ-Track1'!K4 -> 394.5216 | D5: 400
B6: Receive Side Compute (MFLOPS) | C6: ='Decoder-Track1'!S42 -> 296.832 | D6: 300
B10: LATENCY
B13: Transmit Side Algorithmic Latency (ms) | C13: ='Encoder-Track1'!O39/'Encoder-Track1'!C3*1000 -> 10
B14: Receive Side Algorithmic Latency (ms) | C14: ='Decoder-Track1'!O42/'Encoder-Track1'!C3*1000 -> 10
B15: Buffering Latency (ms) | C15: ='Encoder-Track1'!M39/'Encoder-Track1'!C3*1000 -> 10
B16: Total Latency (ms) | C16: =SUM(C13:C15) -> 30
B17: LRAC Challenge Budget (ms) | C17: 30

Sheet Encoder-Track2
B2: Duration (samples) | C2: =M50*1000000 -> 240000000
B3: Sampling rate | C3: 24000
B4: Duration (sec) | C4: =C2/C3 -> 10000
B7: Layer Name | C7: block ID | D7: kernel size | E7: input channels | F7: output channels | G7: dilation | H7: stride | I7: alignment | J7: FOV left (in samples) | K7: FOV right (in samples) | L7: padding left | M7: padding right | N7: extra padding right | O7: padded input length | P7: output length | Q7: #Params | R7: #MAC | S7: MMAC/s
B8: Input Conv | C8: Input Conv | D8: 7 | E8: 1 | F8: 8 | G8: 1 | H8: 1 | I8: 1 | J8: =$I8*($D8-1)*$G8 -> 6 | K8: =(1-$I8)*($D8-1)*$G8 -> 0 | L8: =(($D8-1)*$G8+1-$H8)*$I8 -> 6 | M8: =(($D8-1)*$G8+1-$H8)*(1-$I8) -> 0 | N8: =CEILING((C2-H8)/H8+1, 1)*H8-C2 -> 0 | O8: =C2+L8+M8+N8 -> 240000006 | P8: =(O8-G8*(D8-1)-1)/H8+1 -> 240000000 | Q8: =D8*E8*F8 -> 56 | R8: =P8*D8*E8*F8 -> 13440000000 | S8: =R8/10^6/$C$4 -> 1.344
B9: Conv1_1 | C9: Residual Stack 1 | D9: 7 | E9: =F8 -> 8 | F9: =F8 -> 8 | G9: 3 | H9: 1 | I9: 1 | J9: =$I9*($D9-1)*$G9*PRODUCT(H8:H8) -> 18 | K9: =(1-$I9)*($D9-1)*$G9*PRODUCT(H8:H8) -> 0 | L9: =(($D9-1)*$G9+1-$H9)*$I9 -> 18 | M9: =(($D9-1)*$G9+1-$H9)*(1-$I9) -> 0 | N9: =CEILING((P8-H9)/H9+1, 1)*H9-P8 -> 0 | O9: =P8+L9+M9+N9 -> 240000018 | P9: =(O9-G9*(D9-1)-1)/H9+1 -> 240000000 | Q9: =D9*E9*F9 -> 448 | R9: =P9*D9*E9*F9 -> 107520000000 | S9: =R9/10^6/$C$4 -> 10.752
B10: Conv1_2 | C10: Residual Stack 1 | D10: 3 | E10: =F9 -> 8 | F10: =F8 -> 8 | G10: 1 | H10: 1 | I10: 1 | J10: =$I10*($D10-1)*$G10*PRODUCT(H8:H9) -> 2 | K10: =(1-$I10)*($D10-1)*$G10*PRODUCT(H8:H9) -> 0 | L10: =(($D10-1)*$G10+1-$H10)*$I10 -> 2 | M10: =(($D10-1)*$G10+1-$H10)*(1-$I10) -> 0 | N10: =CEILING((P9-H10)/H10+1, 1)*H10-P9 -> 0 | O10: =P9+L10+M10+N10 -> 240000002 | P10: =(O10-G10*(D10-1)-1)/H10+1 -> 240000000 | Q10: =D10*E10*F10 -> 192 | R10: =P10*D10*E10*F10 -> 46080000000 | S10: =R10/10^6/$C$4 -> 4.608
B11: Conv1_3 | C11: Residual Stack 1 | D11: 7 | E11: =F10 -> 8 | F11: =F8 -> 8 | G11: 9 | H11: 1 | I11: 1 | J11: =$I11*($D11-1)*$G11*PRODUCT(H8:H10) -> 54 | K11: =(1-$I11)*($D11-1)*$G11*PRODUCT(H8:H10) -> 0 | L11: =(($D11-1)*$G11+1-$H11)*$I11 -> 54 | M11: =(($D11-1)*$G11+1-$H11)*(1-$I11) -> 0 | N11: =CEILING((P10-H11)/H11+1, 1)*H11-P10 -> 0 | O11: =P10+L11+M11+N11 -> 240000054 | P11: =(O11-G11*(D11-1)-1)/H11+1 -> 240000000 | Q11: =D11*E11*F11 -> 448 | R11: =P11*D11*E11*F11 -> 107520000000 | S11: =R11/10^6/$C$4 -> 10.752
B12: Conv1_4 | C12: Residual Stack 1 | D12: 3 | E12: =F11 -> 8 | F12: =F8 -> 8 | G12: 1 | H12: 1 | I12: 1 | J12: =$I12*($D12-1)*$G12*PRODUCT(H8:H11) -> 2 | K12: =(1-$I12)*($D12-1)*$G12*PRODUCT(H8:H11) -> 0 | L12: =(($D12-1)*$G12+1-$H12)*$I12 -> 2 | M12: =(($D12-1)*$G12+1-$H12)*(1-$I12) -> 0 | N12: =CEILING((P11-H12)/H12+1, 1)*H12-P11 -> 0 | O12: =P11+L12+M12+N12 -> 240000002 | P12: =(O12-G12*(D12-1)-1)/H12+1 -> 240000000 | Q12: =D12*E12*F12 -> 192 | R12: =P12*D12*E12*F12 -> 46080000000 | S12: =R12/10^6/$C$4 -> 4.608
B13: Conv1_5 | C13: Residual Stack 1 | D13: 7 | E13: =F12 -> 8 | F13: =F8 -> 8 | G13: 27 | H13: 1 | I13: 1 | J13: =$I13*($D13-1)*$G13*PRODUCT(H8:H12) -> 162 | K13: =(1-$I13)*($D13-1)*$G13*PRODUCT(H8:H12) -> 0 | L13: =(($D13-1)*$G13+1-$H13)*$I13 -> 162 | M13: =(($D13-1)*$G13+1-$H13)*(1-$I13) -> 0 | N13: =CEILING((P12-H13)/H13+1, 1)*H13-P12 -> 0 | O13: =P12+L13+M13+N13 -> 240000162 | P13: =(O13-G13*(D13-1)-1)/H13+1 -> 240000000 | Q13: =D13*E13*F13 -> 448 | R13: =P13*D13*E13*F13 -> 107520000000 | S13: =R13/10^6/$C$4 -> 10.752
B14: Conv1_6 | C14: Residual Stack 1 | D14: 3 | E14: =F13 -> 8 | F14: =F8 -> 8 | G14: 1 | H14: 1 | I14: 1 | J14: =$I14*($D14-1)*$G14*PRODUCT(H8:H13) -> 2 | K14: =(1-$I14)*($D14-1)*$G14*PRODUCT(H8:H13) -> 0 | L14: =(($D14-1)*$G14+1-$H14)*$I14 -> 2 | M14: =(($D14-1)*$G14+1-$H14)*(1-$I14) -> 0 | N14: =CEILING((P13-H14)/H14+1, 1)*H14-P13 -> 0 | O14: =P13+L14+M14+N14 -> 240000002 | P14: =(O14-G14*(D14-1)-1)/H14+1 -> 240000000 | Q14: =D14*E14*F14 -> 192 | R14: =P14*D14*E14*F14 -> 46080000000 | S14: =R14/10^6/$C$4 -> 4.608
B15: Conv1_7 | C15: Residual Stack 1 | D15: 7 | E15: =F14 -> 8 | F15: =F8 -> 8 | G15: 81 | H15: 1 | I15: 1 | J15: =$I15*($D15-1)*$G15*PRODUCT(H8:H14) -> 486 | K15: =(1-$I15)*($D15-1)*$G15*PRODUCT(H8:H14) -> 0 | L15: =(($D15-1)*$G15+1-$H15)*$I15 -> 486 | M15: =(($D15-1)*$G15+1-$H15)*(1-$I15) -> 0 | N15: =CEILING((P14-H15)/H15+1, 1)*H15-P14 -> 0 | O15: =P14+L15+M15+N15 -> 240000486 | P15: =(O15-G15*(D15-1)-1)/H15+1 -> 240000000 | Q15: =D15*E15*F15 -> 448 | R15: =P15*D15*E15*F15 -> 107520000000 | S15: =R15/10^6/$C$4 -> 10.752
B16: Conv1_8 | C16: Residual Stack 1 | D16: 3 | E16: =F15 -> 8 | F16: =F8 -> 8 | G16: 1 | H16: 1 | I16: 1 | J16: =$I16*($D16-1)*$G16*PRODUCT(H8:H15) -> 2 | K16: =(1-$I16)*($D16-1)*$G16*PRODUCT(H8:H15) -> 0 | L16: =(($D16-1)*$G16+1-$H16)*$I16 -> 2 | M16: =(($D16-1)*$G16+1-$H16)*(1-$I16) -> 0 | N16: =CEILING((P15-H16)/H16+1, 1)*H16-P15 -> 0 | O16: =P15+L16+M16+N16 -> 240000002 | P16: =(O16-G16*(D16-1)-1)/H16+1 -> 240000000 | Q16: =D16*E16*F16 -> 192 | R16: =P16*D16*E16*F16 -> 46080000000 | S16: =R16/10^6/$C$4 -> 4.608
B17: Conv1_9 | C17: Strided Conv 1 | D17: =2*H17 -> 4 | E17: =F16 -> 8 | F17: 16 | G17: 1 | H17: 2 | I17: 1 | J17: =$I17*($D17-1)*$G17*PRODUCT(H8:H16) -> 3 | K17: =(1-$I17)*($D17-1)*$G17*PRODUCT(H8:H16) -> 0 | L17: =(($D17-1)*$G17+1-$H17)*$I17 -> 2 | M17: =(($D17-1)*$G17+1-$H17)*(1-$I17) -> 0 | N17: =CEILING((P16-H17)/H17+1, 1)*H17-P16 -> 0 | O17: =P16+L17+M17+N17 -> 240000002 | P17: =(O17-G17*(D17-1)-1)/H17+1 -> 120000000 | Q17: =D17*E17*F17 -> 512 | R17: =P17*D17*E17*F17 -> 61440000000 | S17: =R17/10^6/$C$4 -> 6.144
B18: Conv2_1 | C18: Residual Stack 2 | D18: 7 | E18: =F17 -> 16 | F18: =F17 -> 16 | G18: 3 | H18: 1 | I18: 1 | J18: =$I18*($D18-1)*$G18*PRODUCT(H8:H17) -> 36 | K18: =(1-$I18)*($D18-1)*$G18*PRODUCT(H8:H17) -> 0 | L18: =(($D18-1)*$G18+1-$H18)*$I18 -> 18 | M18: =(($D18-1)*$G18+1-$H18)*(1-$I18) -> 0 | N18: =CEILING((P17-H18)/H18+1, 1)*H18-P17 -> 0 | O18: =P17+L18+M18+N18 -> 120000018 | P18: =(O18-G18*(D18-1)-1)/H18+1 -> 120000000 | Q18: =D18*E18*F18 -> 1792 | R18: =P18*D18*E18*F18 -> 215040000000 | S18: =R18/10^6/$C$4 -> 21.504
B19: Conv2_2 | C19: Residual Stack 2 | D19: 3 | E19: =F18 -> 16 | F19: =F17 -> 16 | G19: 1 | H19: 1 | I19: 1 | J19: =$I19*($D19-1)*$G19*PRODUCT(H8:H18) -> 4 | K19: =(1-$I19)*($D19-1)*$G19*PRODUCT(H8:H18) -> 0 | L19: =(($D19-1)*$G19+1-$H19)*$I19 -> 2 | M19: =(($D19-1)*$G19+1-$H19)*(1-$I19) -> 0 | N19: =CEILING((P18-H19)/H19+1, 1)*H19-P18 -> 0 | O19: =P18+L19+M19+N19 -> 120000002 | P19: =(O19-G19*(D19-1)-1)/H19+1 -> 120000000 | Q19: =D19*E19*F19 -> 768 | R19: =P19*D19*E19*F19 -> 92160000000 | S19: =R19/10^6/$C$4 -> 9.216
B20: Conv2_3 | C20: Residual Stack 2 | D20: 7 | E20: =F19 -> 16 | F20: =F17 -> 16 | G20: 9 | H20: 1 | I20: 1 | J20: =$I20*($D20-1)*$G20*PRODUCT(H8:H19) -> 108 | K20: =(1-$I20)*($D20-1)*$G20*PRODUCT(H8:H19) -> 0 | L20: =(($D20-1)*$G20+1-$H20)*$I20 -> 54 | M20: =(($D20-1)*$G20+1-$H20)*(1-$I20) -> 0 | N20: =CEILING((P19-H20)/H20+1, 1)*H20-P19 -> 0 | O20: =P19+L20+M20+N20 -> 120000054 | P20: =(O20-G20*(D20-1)-1)/H20+1 -> 120000000 | Q20: =D20*E20*F20 -> 1792 | R20: =P20*D20*E20*F20 -> 215040000000 | S20: =R20/10^6/$C$4 -> 21.504
B21: Conv2_4 | C21: Residual Stack 2 | D21: 3 | E21: =F20 -> 16 | F21: =F17 -> 16 | G21: 1 | H21: 1 | I21: 1 | J21: =$I21*($D21-1)*$G21*PRODUCT(H8:H20) -> 4 | K21: =(1-$I21)*($D21-1)*$G21*PRODUCT(H8:H20) -> 0 | L21: =(($D21-1)*$G21+1-$H21)*$I21 -> 2 | M21: =(($D21-1)*$G21+1-$H21)*(1-$I21) -> 0 | N21: =CEILING((P20-H21)/H21+1, 1)*H21-P20 -> 0 | O21: =P20+L21+M21+N21 -> 120000002 | P21: =(O21-G21*(D21-1)-1)/H21+1 -> 120000000 | Q21: =D21*E21*F21 -> 768 | R21: =P21*D21*E21*F21 -> 92160000000 | S21: =R21/10^6/$C$4 -> 9.216
B22: Conv2_5 | C22: Residual Stack 2 | D22: 7 | E22: =F21 -> 16 | F22: =F17 -> 16 | G22: 27 | H22: 1 | I22: 1 | J22: =$I22*($D22-1)*$G22*PRODUCT(H8:H21) -> 324 | K22: =(1-$I22)*($D22-1)*$G22*PRODUCT(H8:H21) -> 0 | L22: =(($D22-1)*$G22+1-$H22)*$I22 -> 162 | M22: =(($D22-1)*$G22+1-$H22)*(1-$I22) -> 0 | N22: =CEILING((P21-H22)/H22+1, 1)*H22-P21 -> 0 | O22: =P21+L22+M22+N22 -> 120000162 | P22: =(O22-G22*(D22-1)-1)/H22+1 -> 120000000 | Q22: =D22*E22*F22 -> 1792 | R22: =P22*D22*E22*F22 -> 215040000000 | S22: =R22/10^6/$C$4 -> 21.504
B23: Conv2_6 | C23: Residual Stack 2 | D23: 3 | E23: =F22 -> 16 | F23: =F17 -> 16 | G23: 1 | H23: 1 | I23: 1 | J23: =$I23*($D23-1)*$G23*PRODUCT(H8:H22) -> 4 | K23: =(1-$I23)*($D23-1)*$G23*PRODUCT(H8:H22) -> 0 | L23: =(($D23-1)*$G23+1-$H23)*$I23 -> 2 | M23: =(($D23-1)*$G23+1-$H23)*(1-$I23) -> 0 | N23: =CEILING((P22-H23)/H23+1, 1)*H23-P22 -> 0 | O23: =P22+L23+M23+N23 -> 120000002 | P23: =(O23-G23*(D23-1)-1)/H23+1 -> 120000000 | Q23: =D23*E23*F23 -> 768 | R23: =P23*D23*E23*F23 -> 92160000000 | S23: =R23/10^6/$C$4 -> 9.216
B24: Conv2_7 | C24: Residual Stack 2 | D24: 5 | E24: =F23 -> 16 | F24: =F17 -> 16 | G24: 81 | H24: 1 | I24: 1 | J24: =$I24*($D24-1)*$G24*PRODUCT(H8:H23) -> 648 | K24: =(1-$I24)*($D24-1)*$G24*PRODUCT(H8:H23) -> 0 | L24: =(($D24-1)*$G24+1-$H24)*$I24 -> 324 | M24: =(($D24-1)*$G24+1-$H24)*(1-$I24) -> 0 | N24: =CEILING((P23-H24)/H24+1, 1)*H24-P23 -> 0 | O24: =P23+L24+M24+N24 -> 120000324 | P24: =(O24-G24*(D24-1)-1)/H24+1 -> 120000000 | Q24: =D24*E24*F24 -> 1280 | R24: =P24*D24*E24*F24 -> 153600000000 | S24: =R24/10^6/$C$4 -> 15.36
B25: Conv2_8 | C25: Residual Stack 2 | D25: 3 | E25: =F24 -> 16 | F25: =F17 -> 16 | G25: 1 | H25: 1 | I25: 1 | J25: =$I25*($D25-1)*$G25*PRODUCT(H8:H24) -> 4 | K25: =(1-$I25)*($D25-1)*$G25*PRODUCT(H8:H24) -> 0 | L25: =(($D25-1)*$G25+1-$H25)*$I25 -> 2 | M25: =(($D25-1)*$G25+1-$H25)*(1-$I25) -> 0 | N25: =CEILING((P24-H25)/H25+1, 1)*H25-P24 -> 0 | O25: =P24+L25+M25+N25 -> 120000002 | P25: =(O25-G25*(D25-1)-1)/H25+1 -> 120000000 | Q25: =D25*E25*F25 -> 768 | R25: =P25*D25*E25*F25 -> 92160000000 | S25: =R25/10^6/$C$4 -> 9.216
B26: Conv2_9 | C26: Strided Conv 2 | D26: =2*H26 -> 4 | E26: =F25 -> 16 | F26: 32 | G26: 1 | H26: 2 | I26: 1 | J26: =$I26*($D26-1)*$G26*PRODUCT(H8:H25) -> 6 | K26: =(1-$I26)*($D26-1)*$G26*PRODUCT(H8:H25) -> 0 | L26: =(($D26-1)*$G26+1-$H26)*$I26 -> 2 | M26: =(($D26-1)*$G26+1-$H26)*(1-$I26) -> 0 | N26: =CEILING((P25-H26)/H26+1, 1)*H26-P25 -> 0 | O26: =P25+L26+M26+N26 -> 120000002 | P26: =(O26-G26*(D26-1)-1)/H26+1 -> 60000000 | Q26: =D26*E26*F26 -> 2048 | R26: =P26*D26*E26*F26 -> 122880000000 | S26: =R26/10^6/$C$4 -> 12.288
B27: Conv3_1 | C27: Residual Stack 3 | D27: 7 | E27: =F26 -> 32 | F27: =F26 -> 32 | G27: 3 | H27: 1 | I27: 1 | J27: =$I27*($D27-1)*$G27*PRODUCT(H8:H26) -> 72 | K27: =(1-$I27)*($D27-1)*$G27*PRODUCT(H8:H26) -> 0 | L27: =(($D27-1)*$G27+1-$H27)*$I27 -> 18 | M27: =(($D27-1)*$G27+1-$H27)*(1-$I27) -> 0 | N27: =CEILING((P26-H27)/H27+1, 1)*H27-P26 -> 0 | O27: =P26+L27+M27+N27 -> 60000018 | P27: =(O27-G27*(D27-1)-1)/H27+1 -> 60000000 | Q27: =D27*E27*F27 -> 7168 | R27: =P27*D27*E27*F27 -> 430080000000 | S27: =R27/10^6/$C$4 -> 43.008
B28: Conv3_2 | C28: Residual Stack 3 | D28: 3 | E28: =F27 -> 32 | F28: =F26 -> 32 | G28: 1 | H28: 1 | I28: 1 | J28: =$I28*($D28-1)*$G28*PRODUCT(H8:H27) -> 8 | K28: =(1-$I28)*($D28-1)*$G28*PRODUCT(H8:H27) -> 0 | L28: =(($D28-1)*$G28+1-$H28)*$I28 -> 2 | M28: =(($D28-1)*$G28+1-$H28)*(1-$I28) -> 0 | N28: =CEILING((P27-H28)/H28+1, 1)*H28-P27 -> 0 | O28: =P27+L28+M28+N28 -> 60000002 | P28: =(O28-G28*(D28-1)-1)/H28+1 -> 60000000 | Q28: =D28*E28*F28 -> 3072 | R28: =P28*D28*E28*F28 -> 184320000000 | S28: =R28/10^6/$C$4 -> 18.432
B29: Conv3_3 | C29: Residual Stack 3 | D29: 7 | E29: =F28 -> 32 | F29: =F26 -> 32 | G29: 9 | H29: 1 | I29: 1 | J29: =$I29*($D29-1)*$G29*PRODUCT(H8:H28) -> 216 | K29: =(1-$I29)*($D29-1)*$G29*PRODUCT(H8:H28) -> 0 | L29: =(($D29-1)*$G29+1-$H29)*$I29 -> 54 | M29: =(($D29-1)*$G29+1-$H29)*(1-$I29) -> 0 | N29: =CEILING((P28-H29)/H29+1, 1)*H29-P28 -> 0 | O29: =P28+L29+M29+N29 -> 60000054 | P29: =(O29-G29*(D29-1)-1)/H29+1 -> 60000000 | Q29: =D29*E29*F29 -> 7168 | R29: =P29*D29*E29*F29 -> 430080000000 | S29: =R29/10^6/$C$4 -> 43.008
B30: Conv3_4 | C30: Residual Stack 3 | D30: 3 | E30: =F29 -> 32 | F30: =F26 -> 32 | G30: 1 | H30: 1 | I30: 1 | J30: =$I30*($D30-1)*$G30*PRODUCT(H8:H29) -> 8 | K30: =(1-$I30)*($D30-1)*$G30*PRODUCT(H8:H29) -> 0 | L30: =(($D30-1)*$G30+1-$H30)*$I30 -> 2 | M30: =(($D30-1)*$G30+1-$H30)*(1-$I30) -> 0 | N30: =CEILING((P29-H30)/H30+1, 1)*H30-P29 -> 0 | O30: =P29+L30+M30+N30 -> 60000002 | P30: =(O30-G30*(D30-1)-1)/H30+1 -> 60000000 | Q30: =D30*E30*F30 -> 3072 | R30: =P30*D30*E30*F30 -> 184320000000 | S30: =R30/10^6/$C$4 -> 18.432
B31: Conv3_5 | C31: Residual Stack 3 | D31: 7 | E31: =F30 -> 32 | F31: =F26 -> 32 | G31: 27 | H31: 1 | I31: 1 | J31: =$I31*($D31-1)*$G31*PRODUCT(H8:H30) -> 648 | K31: =(1-$I31)*($D31-1)*$G31*PRODUCT(H8:H30) -> 0 | L31: =(($D31-1)*$G31+1-$H31)*$I31 -> 162 | M31: =(($D31-1)*$G31+1-$H31)*(1-$I31) -> 0 | N31: =CEILING((P30-H31)/H31+1, 1)*H31-P30 -> 0 | O31: =P30+L31+M31+N31 -> 60000162 | P31: =(O31-G31*(D31-1)-1)/H31+1 -> 60000000 | Q31: =D31*E31*F31 -> 7168 | R31: =P31*D31*E31*F31 -> 430080000000 | S31: =R31/10^6/$C$4 -> 43.008
B32: Conv3_6 | C32: Residual Stack 3 | D32: 3 | E32: =F31 -> 32 | F32: =F26 -> 32 | G32: 1 | H32: 1 | I32: 1 | J32: =$I32*($D32-1)*$G32*PRODUCT(H8:H31) -> 8 | K32: =(1-$I32)*($D32-1)*$G32*PRODUCT(H8:H31) -> 0 | L32: =(($D32-1)*$G32+1-$H32)*$I32 -> 2 | M32: =(($D32-1)*$G32+1-$H32)*(1-$I32) -> 0 | N32: =CEILING((P31-H32)/H32+1, 1)*H32-P31 -> 0 | O32: =P31+L32+M32+N32 -> 60000002 | P32: =(O32-G32*(D32-1)-1)/H32+1 -> 60000000 | Q32: =D32*E32*F32 -> 3072 | R32: =P32*D32*E32*F32 -> 184320000000 | S32: =R32/10^6/$C$4 -> 18.432
B33: Conv3_7 | C33: Strided Conv 3 | D33: =2*H33 -> 6 | E33: =F32 -> 32 | F33: 64 | G33: 1 | H33: 3 | I33: 1 | J33: =$I33*($D33-1)*$G33*PRODUCT(H8:H32) -> 20 | K33: =(1-$I33)*($D33-1)*$G33*PRODUCT(H8:H32) -> 0 | L33: =(($D33-1)*$G33+1-$H33)*$I33 -> 3 | M33: =(($D33-1)*$G33+1-$H33)*(1-$I33) -> 0 | N33: =CEILING((P32-H33)/H33+1, 1)*H33-P32 -> 0 | O33: =P32+L33+M33+N33 -> 60000003 | P33: =(O33-G33*(D33-1)-1)/H33+1 -> 20000000 | Q33: =D33*E33*F33 -> 12288 | R33: =P33*D33*E33*F33 -> 245760000000 | S33: =R33/10^6/$C$4 -> 24.576
B34: Conv4_1 | C34: Residual Stack 4 | D34: 7 | E34: =F33 -> 64 | F34: =F33 -> 64 | G34: 3 | H34: 1 | I34: 0.5 | J34: =$I34*($D34-1)*$G34*PRODUCT(H8:H33) -> 108 | K34: =(1-$I34)*($D34-1)*$G34*PRODUCT(H8:H33) -> 108 | L34: =(($D34-1)*$G34+1-$H34)*$I34 -> 9 | M34: =(($D34-1)*$G34+1-$H34)*(1-$I34) -> 9 | N34: =CEILING((P33-H34)/H34+1, 1)*H34-P33 -> 0 | O34: =P33+L34+M34+N34 -> 20000018 | P34: =(O34-G34*(D34-1)-1)/H34+1 -> 20000000 | Q34: =D34*E34*F34 -> 28672 | R34: =P34*D34*E34*F34 -> 573440000000 | S34: =R34/10^6/$C$4 -> 57.344
B35: Conv4_2 | C35: Residual Stack 4 | D35: 3 | E35: =F34 -> 64 | F35: =F33 -> 64 | G35: 1 | H35: 1 | I35: 1 | J35: =$I35*($D35-1)*$G35*PRODUCT(H8:H34) -> 24 | K35: =(1-$I35)*($D35-1)*$G35*PRODUCT(H8:H34) -> 0 | L35: =(($D35-1)*$G35+1-$H35)*$I35 -> 2 | M35: =(($D35-1)*$G35+1-$H35)*(1-$I35) -> 0 | N35: =CEILING((P34-H35)/H35+1, 1)*H35-P34 -> 0 | O35: =P34+L35+M35+N35 -> 20000002 | P35: =(O35-G35*(D35-1)-1)/H35+1 -> 20000000 | Q35: =D35*E35*F35 -> 12288 | R35: =P35*D35*E35*F35 -> 245760000000 | S35: =R35/10^6/$C$4 -> 24.576
B36: Conv4_3 | C36: Residual Stack 4 | D36: 7 | E36: =F35 -> 64 | F36: =F33 -> 64 | G36: 9 | H36: 1 | I36: 0.5 | J36: =$I36*($D36-1)*$G36*PRODUCT(H8:H35) -> 324 | K36: =(1-$I36)*($D36-1)*$G36*PRODUCT(H8:H35) -> 324 | L36: =(($D36-1)*$G36+1-$H36)*$I36 -> 27 | M36: =(($D36-1)*$G36+1-$H36)*(1-$I36) -> 27 | N36: =CEILING((P35-H36)/H36+1, 1)*H36-P35 -> 0 | O36: =P35+L36+M36+N36 -> 20000054 | P36: =(O36-G36*(D36-1)-1)/H36+1 -> 20000000 | Q36: =D36*E36*F36 -> 28672 | R36: =P36*D36*E36*F36 -> 573440000000 | S36: =R36/10^6/$C$4 -> 57.344
B37: Conv4_4 | C37: Residual Stack 4 | D37: 3 | E37: =F36 -> 64 | F37: =F33 -> 64 | G37: 1 | H37: 1 | I37: 1 | J37: =$I37*($D37-1)*$G37*PRODUCT(H8:H36) -> 24 | K37: =(1-$I37)*($D37-1)*$G37*PRODUCT(H8:H36) -> 0 | L37: =(($D37-1)*$G37+1-$H37)*$I37 -> 2 | M37: =(($D37-1)*$G37+1-$H37)*(1-$I37) -> 0 | N37: =CEILING((P36-H37)/H37+1, 1)*H37-P36 -> 0 | O37: =P36+L37+M37+N37 -> 20000002 | P37: =(O37-G37*(D37-1)-1)/H37+1 -> 20000000 | Q37: =D37*E37*F37 -> 12288 | R37: =P37*D37*E37*F37 -> 245760000000 | S37: =R37/10^6/$C$4 -> 24.576
B38: Conv4_5 | C38: Residual Stack 4 | D38: 7 | E38: =F37 -> 64 | F38: =F33 -> 64 | G38: 27 | H38: 1 | I38: 1 | J38: =$I38*($D38-1)*$G38*PRODUCT(H8:H37) -> 1944 | K38: =(1-$I38)*($D38-1)*$G38*PRODUCT(H8:H37) -> 0 | L38: =(($D38-1)*$G38+1-$H38)*$I38 -> 162 | M38: =(($D38-1)*$G38+1-$H38)*(1-$I38) -> 0 | N38: =CEILING((P37-H38)/H38+1, 1)*H38-P37 -> 0 | O38: =P37+L38+M38+N38 -> 20000162 | P38: =(O38-G38*(D38-1)-1)/H38+1 -> 20000000 | Q38: =D38*E38*F38 -> 28672 | R38: =P38*D38*E38*F38 -> 573440000000 | S38: =R38/10^6/$C$4 -> 57.344
B39: Conv4_6 | C39: Residual Stack 4 | D39: 3 | E39: =F38 -> 64 | F39: =F33 -> 64 | G39: 1 | H39: 1 | I39: 1 | J39: =$I39*($D39-1)*$G39*PRODUCT(H8:H38) -> 24 | K39: =(1-$I39)*($D39-1)*$G39*PRODUCT(H8:H38) -> 0 | L39: =(($D39-1)*$G39+1-$H39)*$I39 -> 2 | M39: =(($D39-1)*$G39+1-$H39)*(1-$I39) -> 0 | N39: =CEILING((P38-H39)/H39+1, 1)*H39-P38 -> 0 | O39: =P38+L39+M39+N39 -> 20000002 | P39: =(O39-G39*(D39-1)-1)/H39+1 -> 20000000 | Q39: =D39*E39*F39 -> 12288 | R39: =P39*D39*E39*F39 -> 245760000000 | S39: =R39/10^6/$C$4 -> 24.576
B40: Conv4_7 | C40: Strided Conv 4 | D40: =2*H40 -> 8 | E40: =F39 -> 64 | F40: 128 | G40: 1 | H40: 4 | I40: 1 | J40: =$I40*($D40-1)*$G40*PRODUCT(H8:H39) -> 84 | K40: =(1-$I40)*($D40-1)*$G40*PRODUCT(H8:H39) -> 0 | L40: =(($D40-1)*$G40+1-$H40)*$I40 -> 4 | M40: =(($D40-1)*$G40+1-$H40)*(1-$I40) -> 0 | N40: =CEILING((P39-H40)/H40+1, 1)*H40-P39 -> 0 | O40: =P39+L40+M40+N40 -> 20000004 | P40: =(O40-G40*(D40-1)-1)/H40+1 -> 5000000 | Q40: =D40*E40*F40 -> 65536 | R40: =P40*D40*E40*F40 -> 327680000000 | S40: =R40/10^6/$C$4 -> 32.768
B41: Conv5_1 | C41: Residual Stack 5 | D41: 7 | E41: =F40 -> 128 | F41: =F40 -> 128 | G41: 3 | H41: 1 | I41: 1 | J41: =$I41*($D41-1)*$G41*PRODUCT(H8:H40) -> 864 | K41: =(1-$I41)*($D41-1)*$G41*PRODUCT(H8:H40) -> 0 | L41: =(($D41-1)*$G41+1-$H41)*$I41 -> 18 | M41: =(($D41-1)*$G41+1-$H41)*(1-$I41) -> 0 | N41: =CEILING((P40-H41)/H41+1, 1)*H41-P40 -> 0 | O41: =P40+L41+M41+N41 -> 5000018 | P41: =(O41-G41*(D41-1)-1)/H41+1 -> 5000000 | Q41: =D41*E41*F41 -> 114688 | R41: =P41*D41*E41*F41 -> 573440000000 | S41: =R41/10^6/$C$4 -> 57.344
B42: Conv5_2 | C42: Residual Stack 5 | D42: 3 | E42: =F41 -> 128 | F42: =F40 -> 128 | G42: 1 | H42: 1 | I42: 0.5 | J42: =$I42*($D42-1)*$G42*PRODUCT(H8:H41) -> 48 | K42: =(1-$I42)*($D42-1)*$G42*PRODUCT(H8:H41) -> 48 | L42: =(($D42-1)*$G42+1-$H42)*$I42 -> 1 | M42: =(($D42-1)*$G42+1-$H42)*(1-$I42) -> 1 | N42: =CEILING((P41-H42)/H42+1, 1)*H42-P41 -> 0 | O42: =P41+L42+M42+N42 -> 5000002 | P42: =(O42-G42*(D42-1)-1)/H42+1 -> 5000000 | Q42: =D42*E42*F42 -> 49152 | R42: =P42*D42*E42*F42 -> 245760000000 | S42: =R42/10^6/$C$4 -> 24.576
B43: Conv5_3 | C43: Residual Stack 5 | D43: 7 | E43: =F42 -> 128 | F43: =F40 -> 128 | G43: 9 | H43: 1 | I43: 1 | J43: =$I43*($D43-1)*$G43*PRODUCT(H8:H42) -> 2592 | K43: =(1-$I43)*($D43-1)*$G43*PRODUCT(H8:H42) -> 0 | L43: =(($D43-1)*$G43+1-$H43)*$I43 -> 54 | M43: =(($D43-1)*$G43+1-$H43)*(1-$I43) -> 0 | N43: =CEILING((P42-H43)/H43+1, 1)*H43-P42 -> 0 | O43: =P42+L43+M43+N43 -> 5000054 | P43: =(O43-G43*(D43-1)-1)/H43+1 -> 5000000 | Q43: =D43*E43*F43 -> 114688 | R43: =P43*D43*E43*F43 -> 573440000000 | S43: =R43/10^6/$C$4 -> 57.344
...

Sheet VQ-Track2
B3: Embedding Dimension | C3: Projection Dimension | D3: Codebook Size | E3: #Layers | F3: Frame Rate | G3: MMAC/s - Input Projections | H3: MMAC/s-Distance Calculation | I3: MMAC/s-Output Projection | J3: Total MFLOPS | K3: Total MFLOPS w/o OP
B4: 320 | C4: 24 | D4: 1024 | E4: 6 | F4: 100 | G4: =F4*B4*C4*E4/10^6 -> 4.608 | H4: =F4*C4*D4*E4/10^6 -> 14.7456 | I4: =F4*C4*B4*E4/10^6 -> 4.608 | J4: =SUM(G4:I4)*2 -> 47.9232 | K4: =SUM(G4:H4)*2 -> 38.7072
B7: Total MFLOPS w/o OP: | C7: Total Computational Complaxity in MFLOPS without output projections.
C8: Note that output projections can be optimized out after training by applying them to the codewords and storing two codebooks, one for transmit side and one for receive side with the downside of increasing binary size

Sheet Decoder-Track2
B3: Input Length (frames) | C3: 300000
B4: Frame rate (Hz) | C4: 100
B5: Duration (sec) | C5: =C3/C4 -> 3000
B6: Input Dimension | C6: 320
B7: Samples Per Frame | C7: 240
B9: Layer Name | C9: blk ID | D9: kerrnel_size | E9: input_channels | F9: output_channels | G9: dilation | H9: stride | I9: alignment | J9: FOV_left | K9: FOV_right | L9: padding left | M9: padding right | N9: extra padding right | O9: padded input length | P9: out_x | Q9: no. of Params | R9: no. of Mac | S9: MMac/s
B10: TransposedConv1 | C10: Upsampling 1 | D10: 5 | E10: =E5 -> 0 | F10: 96 | G10: 1 | H10: 5 | I10: 1 | J10: =(D10-H10)*(1-I10) -> 0 | K10: =(D10-H10)*I10 -> 0 | L10: =(D10-H10)*I10 -> 0 | M10: =(D10-H10)*(1-I10) -> 0 | N10: 0 | O10: =C3 -> 300000 | P10: =($C$3-1)*H10+G10*(D10-1)+1+L10+M10 -> 1500000 | Q10: =D10*E10*F10 -> 0 | R10: =C3*D10*E10*F10 -> 0 | S10: =R10/C5/10^6 -> 0
B11: Conv1_1 | C11: ResidualStack1 | D11: 3 | E11: =F10 -> 96 | F11: =F10 -> 96 | G11: 5 | H11: 1 | I11: 0.5 | J11: =IF($G11=1, I11*($D11-1)/H10, I11*($D11-1)*$G11/H10) -> 1 | K11: =IF($G11=1, (1-I11)*($D11-1)/H10, (1-I11)*($D11-1)*$G11/H10) -> 1 | L11: =((D11-1)*G11+1-H11)*I11 -> 5 | M11: =((D11-1)*G11+1-H11)*(1-I11) -> 5 | N11: =CEILING((P10-H11)/H11+1, 1)*H11-P10 -> 0 | O11: =P10+L11+M11+N11 -> 1500010 | P11: =O11-G11*(D11-1) -> 1500000 | Q11: =D11*E11*F11 -> 27648 | R11: =P11*D11*E11*F11 -> 41472000000 | S11: =R11/C5/10^6 -> 13.824
B12: Conv1_2 | C12: ResidualStack1 | D12: 1 | E12: =F11 -> 96 | F12: =F10 -> 96 | G12: 1 | H12: 1 | I12: 1 | J12: =IF($G12=1, ($D12-1)/H10, ($D12-1)*$G12/H10) -> 0 | K12: 0 | L12: =((D12-1)*G12+1-H12)*I12 -> 0 | M12: =((D12-1)*G12+1-H12)*(1-I12) -> 0 | N12: =CEILING((P11-H12)/H12+1, 1)*H12-P11 -> 0 | O12: =P11+L12+M12+N12 -> 1500000 | P12: =O12-G12*(D12-1) -> 1500000 | Q12: =D12*E12*F12 -> 9216 | R12: =P12*D12*E12*F12 -> 13824000000 | S12: =R12/C5/10^6 -> 4.608
B13: Conv1_3 | C13: ResidualStack1 | D13: 3 | E13: =F12 -> 96 | F13: =F10 -> 96 | G13: 5 | H13: 1 | I13: 0.5 | J13: =IF($G13=1, I13*($D13-1)/H10, I13*($D13-1)*$G13/H10) -> 1 | K13: =IF($G13=1, (1-I13)*($D13-1)/H10, (1-I13)*($D13-1)*$G13/H10) -> 1 | L13: =((D13-1)*G13+1-H13)*I13 -> 5 | M13: =((D13-1)*G13+1-H13)*(1-I13) -> 5 | N13: =CEILING((P12-H13)/H13+1, 1)*H13-P12 -> 0 | O13: =P12+L13+M13+N13 -> 1500010 | P13: =O13-G13*(D13-1) -> 1500000 | Q13: =D13*E13*F13 -> 27648 | R13: =P13*D13*E13*F13 -> 41472000000 | S13: =R13/C5/10^6 -> 13.824
B14: Conv1_4 | C14: ResidualStack1 | D14: 1 | E14: =F13 -> 96 | F14: =F10 -> 96 | G14: 1 | H14: 1 | I14: 1 | J14: =IF($G14=1, ($D14-1)/H10, ($D14-1)*$G14/H10) -> 0 | K14: =IF($G14=1, (1-I14)*($D14-1)/H11, (1-I14)*($D14-1)*$G14/H11) -> 0 | L14: =((D14-1)*G14+1-H14)*I14 -> 0 | M14: =((D14-1)*G14+1-H14)*(1-I14) -> 0 | N14: =CEILING((P13-H14)/H14+1, 1)*H14-P13 -> 0 | O14: =P13+L14+M14+N14 -> 1500000 | P14: =O14-G14*(D14-1) -> 1500000 | Q14: =D14*E14*F14 -> 9216 | R14: =P14*D14*E14*F14 -> 13824000000 | S14: =R14/C5/10^6 -> 4.608
B15: Conv1_5 | C15: ResidualStack1 | D15: 5 | E15: =F14 -> 96 | F15: =F10 -> 96 | G15: 25 | H15: 1 | I15: 1 | J15: =IF($G15=1, I15*($D15-1)/H10, I15*($D15-1)*$G15/H10) -> 20 | K15: =IF($G15=1, (1-I15)*($D15-1)/H12, (1-I15)*($D15-1)*$G15/H12) -> 0 | L15: =((D15-1)*G15+1-H15)*I15 -> 100 | M15: =((D15-1)*G15+1-H15)*(1-I15) -> 0 | N15: =CEILING((P14-H15)/H15+1, 1)*H15-P14 -> 0 | O15: =P14+L15+M15+N15 -> 1500100 | P15: =O15-G15*(D15-1) -> 1500000 | Q15: =D15*E15*F15 -> 46080 | R15: =P15*D15*E15*F15 -> 69120000000 | S15: =R15/C5/10^6 -> 23.04
B16: Conv1_6 | C16: ResidualStack1 | D16: 1 | E16: =F15 -> 96 | F16: =F10 -> 96 | G16: 1 | H16: 1 | I16: 1 | J16: =IF($G16=1, ($D16-1)/H10, ($D16-1)*$G16/H10) -> 0 | K16: =IF($G16=1, (1-I16)*($D16-1)/H13, (1-I16)*($D16-1)*$G16/H13) -> 0 | L16: =((D16-1)*G16+1-H16)*I16 -> 0 | M16: =((D16-1)*G16+1-H16)*(1-I16) -> 0 | N16: =CEILING((P15-H16)/H16+1, 1)*H16-P15 -> 0 | O16: =P15+L16+M16+N16 -> 1500000 | P16: =O16-G16*(D16-1) -> 1500000 | Q16: =D16*E16*F16 -> 9216 | R16: =P16*D16*E16*F16 -> 13824000000 | S16: =R16/C5/10^6 -> 4.608
B17: TransposedConv2 | C17: Upsampling 2 | D17: 4 | E17: =F16 -> 96 | F17: 48 | G17: 1 | H17: 4 | I17: 1 | J17: =(D17-H17)*(1-I17) -> 0 | K17: =(D17-H17)*I17 -> 0 | L17: =(D17-H17)*I17 -> 0 | M17: =(D17-H17)*(1-I17) -> 0 | N17: 0 | O17: =P16 -> 1500000 | P17: =(P16-1)*H17+G17*(D17-1)+1 -> 6000000 | Q17: =D17*E17*F17 -> 18432 | R17: =P16*D17*E17*F17 -> 27648000000 | S17: =R17/C5/10^6 -> 9.216
B18: Conv2_1 | C18: ResidualStack2 | D18: 3 | E18: =F17 -> 48 | F18: =F17 -> 48 | G18: 4 | H18: 1 | I18: 1 | J18: =IF($G18=1, ($D18-1)/H17/H10, ($D18-1)*$G18/H17/H10) -> 0.4 | K18: =IF($G18=1, (1-I18)*($D18-1)/H15, (1-I18)*($D18-1)*$G18/H15) -> 0 | L18: =((D18-1)*G18+1-H18)*I18 -> 8 | M18: =((D18-1)*G18+1-H18)*(1-I18) -> 0 | N18: =CEILING((P17-H18)/H18+1, 1)*H18-P17 -> 0 | O18: =P17+L18+M18+N18 -> 6000008 | P18: =O18-G18*(D18-1) -> 6000000 | Q18: =D18*E18*F18 -> 6912 | R18: =P18*D18*E18*F18 -> 41472000000 | S18: =R18/C5/10^6 -> 13.824
B19: Conv2_2 | C19: ResidualStack2 | D19: 1 | E19: =F18 -> 48 | F19: =F17 -> 48 | G19: 1 | H19: 1 | I19: 1 | J19: =IF($G19=1, ($D19-1)/H17/H10, ($D19-1)*$G19/H17/H10) -> 0 | K19: =IF($G19=1, (1-I19)*($D19-1)/H16, (1-I19)*($D19-1)*$G19/H16) -> 0 | L19: =((D19-1)*G19+1-H19)*I19 -> 0 | M19: =((D19-1)*G19+1-H19)*(1-I19) -> 0 | N19: =CEILING((P18-H19)/H19+1, 1)*H19-P18 -> 0 | O19: =P18+L19+M19+N19 -> 6000000 | P19: =O19-G19*(D19-1) -> 6000000 | Q19: =D19*E19*F19 -> 2304 | R19: =P19*D19*E19*F19 -> 13824000000 | S19: =R19/C5/10^6 -> 4.608
B20: Conv2_3 | C20: ResidualStack2 | D20: 5 | E20: =F19 -> 48 | F20: =F17 -> 48 | G20: 5 | H20: 1 | I20: 1 | J20: =IF($G20=1, ($D20-1)/H17/H10, ($D20-1)*$G20/H17/H10) -> 1 | K20: =IF($G20=1, (1-I20)*($D20-1)/H17, (1-I20)*($D20-1)*$G20/H17) -> 0 | L20: =((D20-1)*G20+1-H20)*I20 -> 20 | M20: =((D20-1)*G20+1-H20)*(1-I20) -> 0 | N20: =CEILING((P19-H20)/H20+1, 1)*H20-P19 -> 0 | O20: =P19+L20+M20+N20 -> 6000020 | P20: =O20-G20*(D20-1) -> 6000000 | Q20: =D20*E20*F20 -> 11520 | R20: =P20*D20*E20*F20 -> 69120000000 | S20: =R20/C5/10^6 -> 23.04
